Workbook
Name file_anmeldungen: '0. Definitionen'!$B$20
Name file_antritt: '0. Definitionen'!$B$21
Name file_the_punkte: '0. Definitionen'!$B$22
Name letzte_aufg_teilgebiet1: tbl_aufgaben_teilgebiete['#]
Name letzte_aufg_teilgebiet1: tbl_aufgaben_teilgebiete['#]
Name zzMG_Chart1: #REF!
Name zzMG_Chart2: '2. Punkte_Prüfung'!$N$5:$P$24

Sheet 0. Definitionen
A1: Name Prüfung | B1: Finanzierung und Invesition
A2: P.-Nummer | B2: BW 20152 7820010 FI
A3: Semester | B3: Sommer 2025
A5: Teilgebiet 1 | C5: Aufgaben | D5: #
A6: Name | B6: FRM | C6: bis | D6: 13
A7: Kürzel | B7: FRM
A9: Teilgebiet 2
A10: Name | B10: Investition (I)
A11: Kürzel | B11: I
A16: folder_path | B16: path
A17: aktueller Ordnerpfad | B17: {=LEFT(CELL("filename"), SEARCH("\[", CELL("filename")))} -> L:\2. Master\1. FRM\Sommer26\
A19: Standard-Dateinamen | B19: name
A20: Teilnehmerliste HISin One | B20: MBW 20242 3412090 RM-Risikomanagement-SoSe_2025-1.xlsx
A21: Antritt zur Prüfung | B21: Schritt 1 Antritt zur Prüfung.xlsx
A22: THE-Punkte-Antworten | B22: THE_FRM SoSe 2025-Schritt 2 Take Home Exam zum Finanzwirtschaftlichen Risikomanagement (FRM)-Bewertungen.xlsx

Sheet 1. Antritt_Prüfung
A1: Anzahl | B1: nicht erfasst | C1: ® Exportdatei aus Moodle ("Antritt zum Take Home Exam.xlsx") solle per PowerQuery eingelesen werden
A2: =COUNTA(A5:A1048576) -> 28 | B2: =COUNTIF(J5:J529,"NEIN") -> 0 | C2: Dateiname: | D2: Antritt zum Take Home Exam.xlsx
A4: Vollständiger Name | B4: Gruppen | C4: E-Mail-Adresse | D4: Datum | E4: Name | F4: Vorname | G4: Matrikelnummer | H4: erfasst
A5: Stud26, Pseudo | C5: stud26@example.local | D5: 45860.336 | E5: Stud26 | F5: Pseudo | G5: 3513589 | H5: =IF(ISNUMBER(G5),IF(OR(ISERR(MATCH(G5,'2. Punkte_Prüfung'!$A$6:$A$383,0)),ISNA(MATCH(G5,'2. Punkte_Prüfung'!$A$6:$A$383,0))),"NEIN","JA"),"") -> JA
A6: Stud04, Pseudo | C6: stud04@example.local | D6: 45860.338 | E6: Stud04 | F6: Pseudo | G6: 3269604 | H6: =IF(ISNUMBER(G6),IF(OR(ISERR(MATCH(G6,'2. Punkte_Prüfung'!$A$6:$A$383,0)),ISNA(MATCH(G6,'2. Punkte_Prüfung'!$A$6:$A$383,0))),"NEIN","JA"),"") -> JA
A7: Stud29, Pseudo | C7: stud29@example.local | D7: 45860.336 | E7: Stud29 | F7: Pseudo | G7: 3517558 | H7: =IF(ISNUMBER(G7),IF(OR(ISERR(MATCH(G7,'2. Punkte_Prüfung'!$A$6:$A$383,0)),ISNA(MATCH(G7,'2. Punkte_Prüfung'!$A$6:$A$383,0))),"NEIN","JA"),"") -> JA
A8: Stud21, Pseudo | C8: stud21@example.local | D8: 45860.333 | E8: Stud21 | F8: Pseudo | G8: 3478653 | H8: =IF(ISNUMBER(G8),IF(OR(ISERR(MATCH(G8,'2. Punkte_Prüfung'!$A$6:$A$383,0)),ISNA(MATCH(G8,'2. Punkte_Prüfung'!$A$6:$A$383,0))),"NEIN","JA"),"") -> JA
A9: Stud01, Pseudo | C9: stud01@example.local | D9: 45860.348 | E9: Stud01 | F9: Pseudo | G9: 3173903 | H9: =IF(ISNUMBER(G9),IF(OR(ISERR(MATCH(G9,'2. Punkte_Prüfung'!$A$6:$A$383,0)),ISNA(MATCH(G9,'2. Punkte_Prüfung'!$A$6:$A$383,0))),"NEIN","JA"),"") -> JA
A10: Stud15, Pseudo | C10: stud15@example.local | D10: 45860.335 | E10: Stud15 | F10: Pseudo | G10: 3472086 | H10: =IF(ISNUMBER(G10),IF(OR(ISERR(MATCH(G10,'2. Punkte_Prüfung'!$A$6:$A$383,0)),ISNA(MATCH(G10,'2. Punkte_Prüfung'!$A$6:$A$383,0))),"NEIN","JA"),"") -> JA
A11: Stud20, Pseudo | C11: stud20@example.local | D11: 45860.335 | E11: Stud20 | F11: Pseudo | G11: 3478426 | H11: =IF(ISNUMBER(G11),IF(OR(ISERR(MATCH(G11,'2. Punkte_Prüfung'!$A$6:$A$383,0)),ISNA(MATCH(G11,'2. Punkte_Prüfung'!$A$6:$A$383,0))),"NEIN","JA"),"") -> JA
A12: Stud12, Pseudo | C12: stud12@example.local | D12: 45860.338 | E12: Stud12 | F12: Pseudo | G12: 3361157 | H12: =IF(ISNUMBER(G12),IF(OR(ISERR(MATCH(G12,'2. Punkte_Prüfung'!$A$6:$A$383,0)),ISNA(MATCH(G12,'2. Punkte_Prüfung'!$A$6:$A$383,0))),"NEIN","JA"),"") -> JA
A13: Stud18, Pseudo | C13: stud18@example.local | D13: 45860.335 | E13: Stud18 | F13: Pseudo | G13: 3475876 | H13: =IF(ISNUMBER(G13),IF(OR(ISERR(MATCH(G13,'2. Punkte_Prüfung'!$A$6:$A$383,0)),ISNA(MATCH(G13,'2. Punkte_Prüfung'!$A$6:$A$383,0))),"NEIN","JA"),"") -> JA
A14: Stud16, Pseudo | C14: stud16@example.local | D14: 45860.34 | E14: Stud16 | F14: Pseudo | G14: 3474220 | H14: =IF(ISNUMBER(G14),IF(OR(ISERR(MATCH(G14,'2. Punkte_Prüfung'!$A$6:$A$383,0)),ISNA(MATCH(G14,'2. Punkte_Prüfung'!$A$6:$A$383,0))),"NEIN","JA"),"") -> JA
A15: Stud17, Pseudo | C15: stud17@example.local | D15: 45860.334 | E15: Stud17 | F15: Pseudo | G15: 3474262 | H15: =IF(ISNUMBER(G15),IF(OR(ISERR(MATCH(G15,'2. Punkte_Prüfung'!$A$6:$A$383,0)),ISNA(MATCH(G15,'2. Punkte_Prüfung'!$A$6:$A$383,0))),"NEIN","JA"),"") -> JA
A16: Stud27, Pseudo | C16: stud27@example.local | D16: 45860.335 | E16: Stud27 | F16: Pseudo | G16: 3514106 | H16: =IF(ISNUMBER(G16),IF(OR(ISERR(MATCH(G16,'2. Punkte_Prüfung'!$A$6:$A$383,0)),ISNA(MATCH(G16,'2. Punkte_Prüfung'!$A$6:$A$383,0))),"NEIN","JA"),"") -> JA
... A32: Stud24, Pseudo | C32: stud24@example.local | D32: 45860.335 | E32: Stud24 | F32: Pseudo | G32: 3491126 | H32: =IF(ISNUMBER(G32),IF(OR(ISERR(MATCH(G32,'2. Punkte_Prüfung'!$A$6:$A$383,0)),ISNA(MATCH(G32,'2. Punkte_Prüfung'!$A$6:$A$383,0))),"NEIN","JA"),"") -> JA
H33: =IF(ISNUMBER(G33),IF(OR(ISERR(MATCH(G33,'2. Punkte_Prüfung'!$A$6:$A$383,0)),ISNA(MATCH(G33,'2. Punkte_Prüfung'!$A$6:$A$383,0))),"NEIN","JA"),"")
H34: =IF(ISNUMBER(G34),IF(OR(ISERR(MATCH(G34,'2. Punkte_Prüfung'!$A$6:$A$383,0)),ISNA(MATCH(G34,'2. Punkte_Prüfung'!$A$6:$A$383,0))),"NEIN","JA"),"")
H35: =IF(ISNUMBER(G35),IF(OR(ISERR(MATCH(G35,'2. Punkte_Prüfung'!$A$6:$A$383,0)),ISNA(MATCH(G35,'2. Punkte_Prüfung'!$A$6:$A$383,0))),"NEIN","JA"),"")
H36: =IF(ISNUMBER(G36),IF(OR(ISERR(MATCH(G36,'2. Punkte_Prüfung'!$A$6:$A$383,0)),ISNA(MATCH(G36,'2. Punkte_Prüfung'!$A$6:$A$383,0))),"NEIN","JA"),"")
H37: =IF(ISNUMBER(G37),IF(OR(ISERR(MATCH(G37,'2. Punkte_Prüfung'!$A$6:$A$383,0)),ISNA(MATCH(G37,'2. Punkte_Prüfung'!$A$6:$A$383,0))),"NEIN","JA"),"")
H38: =IF(ISNUMBER(G38),IF(OR(ISERR(MATCH(G38,'2. Punkte_Prüfung'!$A$6:$A$383,0)),ISNA(MATCH(G38,'2. Punkte_Prüfung'!$A$6:$A$383,0))),"NEIN","JA"),"")
H39: =IF(ISNUMBER(G39),IF(OR(ISERR(MATCH(G39,'2. Punkte_Prüfung'!$A$6:$A$383,0)),ISNA(MATCH(G39,'2. Punkte_Prüfung'!$A$6:$A$383,0))),"NEIN","JA"),"")
H40: =IF(ISNUMBER(G40),IF(OR(ISERR(MATCH(G40,'2. Punkte_Prüfung'!$A$6:$A$383,0)),ISNA(MATCH(G40,'2. Punkte_Prüfung'!$A$6:$A$383,0))),"NEIN","JA"),"")
H41: =IF(ISNUMBER(G41),IF(OR(ISERR(MATCH(G41,'2. Punkte_Prüfung'!$A$6:$A$383,0)),ISNA(MATCH(G41,'2. Punkte_Prüfung'!$A$6:$A$383,0))),"NEIN","JA"),"")
H42: =IF(ISNUMBER(G42),IF(OR(ISERR(MATCH(G42,'2. Punkte_Prüfung'!$A$6:$A$383,0)),ISNA(MATCH(G42,'2. Punkte_Prüfung'!$A$6:$A$383,0))),"NEIN","JA"),"")
H43: =IF(ISNUMBER(G43),IF(OR(ISERR(MATCH(G43,'2. Punkte_Prüfung'!$A$6:$A$383,0)),ISNA(MATCH(G43,'2. Punkte_Prüfung'!$A$6:$A$383,0))),"NEIN","JA"),"")
H44: =IF(ISNUMBER(G44),IF(OR(ISERR(MATCH(G44,'2. Punkte_Prüfung'!$A$6:$A$383,0)),ISNA(MATCH(G44,'2. Punkte_Prüfung'!$A$6:$A$383,0))),"NEIN","JA"),"")
... H106: =IF(ISNUMBER(G106),IF(OR(ISERR(MATCH(G106,'2. Punkte_Prüfung'!$A$6:$A$383,0)),ISNA(MATCH(G106,'2. Punkte_Prüfung'!$A$6:$A$383,0))),"NEIN","JA"),"")
I107: =IF(ISNUMBER(#REF!),IF(OR(ISERR(MATCH(#REF!,'2. Punkte_Prüfung'!$A$6:$A$383,0)),ISNA(MATCH(#REF!,'2. Punkte_Prüfung'!$A$6:$A$383,0))),"NEIN","JA"),"")
I108: =IF(ISNUMBER(#REF!),IF(OR(ISERR(MATCH(#REF!,'2. Punkte_Prüfung'!$A$6:$A$383,0)),ISNA(MATCH(#REF!,'2. Punkte_Prüfung'!$A$6:$A$383,0))),"NEIN","JA"),"")
I109: =IF(ISNUMBER(#REF!),IF(OR(ISERR(MATCH(#REF!,'2. Punkte_Prüfung'!$A$6:$A$383,0)),ISNA(MATCH(#REF!,'2. Punkte_Prüfung'!$A$6:$A$383,0))),"NEIN","JA"),"")
I110: =IF(ISNUMBER(#REF!),IF(OR(ISERR(MATCH(#REF!,'2. Punkte_Prüfung'!$A$6:$A$383,0)),ISNA(MATCH(#REF!,'2. Punkte_Prüfung'!$A$6:$A$383,0))),"NEIN","JA"),"")
I111: =IF(ISNUMBER(#REF!),IF(OR(ISERR(MATCH(#REF!,'2. Punkte_Prüfung'!$A$6:$A$383,0)),ISNA(MATCH(#REF!,'2. Punkte_Prüfung'!$A$6:$A$383,0))),"NEIN","JA"),"")
I112: =IF(ISNUMBER(#REF!),IF(OR(ISERR(MATCH(#REF!,'2. Punkte_Prüfung'!$A$6:$A$383,0)),ISNA(MATCH(#REF!,'2. Punkte_Prüfung'!$A$6:$A$383,0))),"NEIN","JA"),"")
I113: =IF(ISNUMBER(#REF!),IF(OR(ISERR(MATCH(#REF!,'2. Punkte_Prüfung'!$A$6:$A$383,0)),ISNA(MATCH(#REF!,'2. Punkte_Prüfung'!$A$6:$A$383,0))),"NEIN","JA"),"")
I114: =IF(ISNUMBER(#REF!),IF(OR(ISERR(MATCH(#REF!,'2. Punkte_Prüfung'!$A$6:$A$383,0)),ISNA(MATCH(#REF!,'2. Punkte_Prüfung'!$A$6:$A$383,0))),"NEIN","JA"),"")
I115: =IF(ISNUMBER(#REF!),IF(OR(ISERR(MATCH(#REF!,'2. Punkte_Prüfung'!$A$6:$A$383,0)),ISNA(MATCH(#REF!,'2. Punkte_Prüfung'!$A$6:$A$383,0))),"NEIN","JA"),"")
I116: =IF(ISNUMBER(#REF!),IF(OR(ISERR(MATCH(#REF!,'2. Punkte_Prüfung'!$A$6:$A$383,0)),ISNA(MATCH(#REF!,'2. Punkte_Prüfung'!$A$6:$A$383,0))),"NEIN","JA"),"")
I117: =IF(ISNUMBER(#REF!),IF(OR(ISERR(MATCH(#REF!,'2. Punkte_Prüfung'!$A$6:$A$383,0)),ISNA(MATCH(#REF!,'2. Punkte_Prüfung'!$A$6:$A$383,0))),"NEIN","JA"),"")
...

Sheet 2. Punkte_Prüfung
A1: Anzahl
A2: =COUNT(Gesamtpunkte[Matr.-Nr.]) -> 28 | L2: Versuche | M2: Anteil | Z2: Zweit- und Drittversuche
K3: fehlende | L3: =COUNTIF($L$6:$L$1048576,2) -> 0 | M3: =L3/A2 -> 0 | N3: Punkteverteilungen
E4: =G4+H4 -> 90 | G4: 45 | H4: 45 | K4: =COUNTIF(Gesamtpunkte[in QIS],"NEIN") -> 0 | L4: =COUNTIF($L$6:$L$1048576,3) -> 0 | M4: =L4/A2 -> 0 | S4: Finanzierung | U4: Investition
A5: Matr.-Nr. | B5: Nachname | C5: Vorname | D5: Note | E5: Gesamtpunkte | F5: Gesamt % | G5: Punkte F | H5: Punkte I | I5: F % | J5: I % | K5: in QIS | L5: Versuch | N5: Gesamt | O5: Anzahl | P5: Anteil | R5: Teilgebiete | S5: Anzahl | T5: Anteil | U5: Anzahl | V5: Anteil
A6: ='2a.Detailpunkte'!D4 -> 3376139 | B6: ='2a.Detailpunkte'!E4 -> Stud14 | C6: ='2a.Detailpunkte'!F4 -> Pseudo | D6: =INDEX('3. Notenszenarien'!$I$6:$I$350,MATCH(Gesamtpunkte[[#This Row],[Matr.-Nr.]],'3. Notenszenarien'!$A$6:$A$1048576,0)) -> 2.3 | E6: =ROUNDUP(INDEX('2a.Detailpunkte'!$A$4:$A$352,MATCH('2. Punkte_Prüfung'!A6,'2a.Detailpunkte'!$D$4:$D$352,0),1)/5,1)*5 -> 70.5 | F6: =Gesamtpunkte[[#This Row],[Gesamtpunkte ]]/$E$4 -> 0.78333333 | G6: =INDEX('2a.Detailpunkte'!$B$4:$B$352,MATCH('2. Punkte_Prüfung'!A6,'2a.Detailpunkte'!$D$4:$D$352,0),1) -> 70.33 | H6: =INDEX('2a.Detailpunkte'!$C$4:$C$352,MATCH('2. Punkte_Prüfung'!A6,'2a.Detailpunkte'!$D$4:$D$352,0),1) -> 0 | I6: =Gesamtpunkte[[#This Row],[Punkte F]]/$G$4 -> 1.5628889 | J6: =Gesamtpunkte[[#This Row],[Punkte I]]/$H$4 -> 0 | K6: =IF(AND(ISNA(MATCH(Gesamtpunkte[[#This Row],[Matr.-Nr.]],'4. Noteneintrag'!$C$11:$C$1048576,0)),ISNUMBER(Gesamtpunkte[[#This Row],[Matr.-Nr.]])),"NEIN","JA") -> JA | N6: 0 | O6: {=FREQUENCY(IF(ISNUMBER(E6:E255),E6:E255,""),N6:N24)} -> 0 | P6: =O6/$O$25 -> 0 | R6: 0 | S6: {=FREQUENCY(IF(ISNUMBER(G6:G255),G6:G255,""),R6:R15)} -> 0 | T6: =S6/$S$16 -> #DIV/0! | U6: {=FREQUENCY(IF(ISNUMBER(H6:H255),H6:H255,""),R6:R15)} -> 28 | V6: =U6/$U$16 -> 1
A7: ='2a.Detailpunkte'!D5 -> 3517558 | B7: ='2a.Detailpunkte'!E5 -> Stud29 | C7: ='2a.Detailpunkte'!F5 -> Pseudo | D7: =INDEX('3. Notenszenarien'!$I$6:$I$350,MATCH(Gesamtpunkte[[#This Row],[Matr.-Nr.]],'3. Notenszenarien'!$A$6:$A$1048576,0)) -> 2.3 | E7: =ROUNDUP(INDEX('2a.Detailpunkte'!$A$4:$A$352,MATCH('2. Punkte_Prüfung'!A7,'2a.Detailpunkte'!$D$4:$D$352,0),1)/5,1)*5 -> 68 | F7: =Gesamtpunkte[[#This Row],[Gesamtpunkte ]]/$E$4 -> 0.75555556 | G7: =INDEX('2a.Detailpunkte'!$B$4:$B$352,MATCH('2. Punkte_Prüfung'!A7,'2a.Detailpunkte'!$D$4:$D$352,0),1) -> 68 | H7: =INDEX('2a.Detailpunkte'!$C$4:$C$352,MATCH('2. Punkte_Prüfung'!A7,'2a.Detailpunkte'!$D$4:$D$352,0),1) -> 0 | I7: =Gesamtpunkte[[#This Row],[Punkte F]]/$G$4 -> 1.5111111 | J7: =Gesamtpunkte[[#This Row],[Punkte I]]/$H$4 -> 0 | K7: =IF(AND(ISNA(MATCH(Gesamtpunkte[[#This Row],[Matr.-Nr.]],'4. Noteneintrag'!$C$11:$C$1048576,0)),ISNUMBER(Gesamtpunkte[[#This Row],[Matr.-Nr.]])),"NEIN","JA") -> JA | N7: 5 | O7: 0 | P7: =O7/$O$25 -> 0 | R7: 5 | S7: 0 | T7: =S7/$S$16 -> #DIV/0! | U7: 0 | V7: =U7/$U$16 -> 0
A8: ='2a.Detailpunkte'!D6 -> 3374601 | B8: ='2a.Detailpunkte'!E6 -> Stud13 | C8: ='2a.Detailpunkte'!F6 -> Pseudo | D8: =INDEX('3. Notenszenarien'!$I$6:$I$350,MATCH(Gesamtpunkte[[#This Row],[Matr.-Nr.]],'3. Notenszenarien'!$A$6:$A$1048576,0)) -> 2.3 | E8: =ROUNDUP(INDEX('2a.Detailpunkte'!$A$4:$A$352,MATCH('2. Punkte_Prüfung'!A8,'2a.Detailpunkte'!$D$4:$D$352,0),1)/5,1)*5 -> 71.5 | F8: =Gesamtpunkte[[#This Row],[Gesamtpunkte ]]/$E$4 -> 0.79444444 | G8: =INDEX('2a.Detailpunkte'!$B$4:$B$352,MATCH('2. Punkte_Prüfung'!A8,'2a.Detailpunkte'!$D$4:$D$352,0),1) -> 71.83 | H8: =INDEX('2a.Detailpunkte'!$C$4:$C$352,MATCH('2. Punkte_Prüfung'!A8,'2a.Detailpunkte'!$D$4:$D$352,0),1) -> 0 | I8: =Gesamtpunkte[[#This Row],[Punkte F]]/$G$4 -> 1.5962222 | J8: =Gesamtpunkte[[#This Row],[Punkte I]]/$H$4 -> 0 | K8: =IF(AND(ISNA(MATCH(Gesamtpunkte[[#This Row],[Matr.-Nr.]],'4. Noteneintrag'!$C$11:$C$1048576,0)),ISNUMBER(Gesamtpunkte[[#This Row],[Matr.-Nr.]])),"NEIN","JA") -> JA | N8: 10 | O8: 0 | P8: =O8/$O$25 -> 0 | R8: 10 | S8: 0 | T8: =S8/$S$16 -> #DIV/0! | U8: 0 | V8: =U8/$U$16 -> 0
A9: ='2a.Detailpunkte'!D7 -> 3516593 | B9: ='2a.Detailpunkte'!E7 -> Stud28 | C9: ='2a.Detailpunkte'!F7 -> Pseudo | D9: =INDEX('3. Notenszenarien'!$I$6:$I$350,MATCH(Gesamtpunkte[[#This Row],[Matr.-Nr.]],'3. Notenszenarien'!$A$6:$A$1048576,0)) -> 1.7 | E9: =ROUNDUP(INDEX('2a.Detailpunkte'!$A$4:$A$352,MATCH('2. Punkte_Prüfung'!A9,'2a.Detailpunkte'!$D$4:$D$352,0),1)/5,1)*5 -> 79 | F9: =Gesamtpunkte[[#This Row],[Gesamtpunkte ]]/$E$4 -> 0.87777778 | G9: =INDEX('2a.Detailpunkte'!$B$4:$B$352,MATCH('2. Punkte_Prüfung'!A9,'2a.Detailpunkte'!$D$4:$D$352,0),1) -> 78.83 | H9: =INDEX('2a.Detailpunkte'!$C$4:$C$352,MATCH('2. Punkte_Prüfung'!A9,'2a.Detailpunkte'!$D$4:$D$352,0),1) -> 0 | I9: =Gesamtpunkte[[#This Row],[Punkte F]]/$G$4 -> 1.7517778 | J9: =Gesamtpunkte[[#This Row],[Punkte I]]/$H$4 -> 0 | K9: =IF(AND(ISNA(MATCH(Gesamtpunkte[[#This Row],[Matr.-Nr.]],'4. Noteneintrag'!$C$11:$C$1048576,0)),ISNUMBER(Gesamtpunkte[[#This Row],[Matr.-Nr.]])),"NEIN","JA") -> JA | N9: 15 | O9: 0 | P9: =O9/$O$25 -> 0 | R9: 15 | S9: 0 | T9: =S9/$S$16 -> #DIV/0! | U9: 0 | V9: =U9/$U$16 -> 0
A10: ='2a.Detailpunkte'!D8 -> 3474262 | B10: ='2a.Detailpunkte'!E8 -> Stud17 | C10: ='2a.Detailpunkte'!F8 -> Pseudo | D10: =INDEX('3. Notenszenarien'!$I$6:$I$350,MATCH(Gesamtpunkte[[#This Row],[Matr.-Nr.]],'3. Notenszenarien'!$A$6:$A$1048576,0)) -> 2 | E10: =ROUNDUP(INDEX('2a.Detailpunkte'!$A$4:$A$352,MATCH('2. Punkte_Prüfung'!A10,'2a.Detailpunkte'!$D$4:$D$352,0),1)/5,1)*5 -> 74.5 | F10: =Gesamtpunkte[[#This Row],[Gesamtpunkte ]]/$E$4 -> 0.82777778 | G10: =INDEX('2a.Detailpunkte'!$B$4:$B$352,MATCH('2. Punkte_Prüfung'!A10,'2a.Detailpunkte'!$D$4:$D$352,0),1) -> 74.33 | H10: =INDEX('2a.Detailpunkte'!$C$4:$C$352,MATCH('2. Punkte_Prüfung'!A10,'2a.Detailpunkte'!$D$4:$D$352,0),1) -> 0 | I10: =Gesamtpunkte[[#This Row],[Punkte F]]/$G$4 -> 1.6517778 | J10: =Gesamtpunkte[[#This Row],[Punkte I]]/$H$4 -> 0 | K10: =IF(AND(ISNA(MATCH(Gesamtpunkte[[#This Row],[Matr.-Nr.]],'4. Noteneintrag'!$C$11:$C$1048576,0)),ISNUMBER(Gesamtpunkte[[#This Row],[Matr.-Nr.]])),"NEIN","JA") -> JA | N10: 20 | O10: 0 | P10: =O10/$O$25 -> 0 | R10: 20 | S10: 0 | T10: =S10/$S$16 -> #DIV/0! | U10: 0 | V10: =U10/$U$16 -> 0
A11: ='2a.Detailpunkte'!D9 -> 3474220 | B11: ='2a.Detailpunkte'!E9 -> Stud16 | C11: ='2a.Detailpunkte'!F9 -> Pseudo | D11: =INDEX('3. Notenszenarien'!$I$6:$I$350,MATCH(Gesamtpunkte[[#This Row],[Matr.-Nr.]],'3. Notenszenarien'!$A$6:$A$1048576,0)) -> 2.7 | E11: =ROUNDUP(INDEX('2a.Detailpunkte'!$A$4:$A$352,MATCH('2. Punkte_Prüfung'!A11,'2a.Detailpunkte'!$D$4:$D$352,0),1)/5,1)*5 -> 66.5 | F11: =Gesamtpunkte[[#This Row],[Gesamtpunkte ]]/$E$4 -> 0.73888889 | G11: =INDEX('2a.Detailpunkte'!$B$4:$B$352,MATCH('2. Punkte_Prüfung'!A11,'2a.Detailpunkte'!$D$4:$D$352,0),1) -> 66.5 | H11: =INDEX('2a.Detailpunkte'!$C$4:$C$352,MATCH('2. Punkte_Prüfung'!A11,'2a.Detailpunkte'!$D$4:$D$352,0),1) -> 0 | I11: =Gesamtpunkte[[#This Row],[Punkte F]]/$G$4 -> 1.4777778 | J11: =Gesamtpunkte[[#This Row],[Punkte I]]/$H$4 -> 0 | K11: =IF(AND(ISNA(MATCH(Gesamtpunkte[[#This Row],[Matr.-Nr.]],'4. Noteneintrag'!$C$11:$C$1048576,0)),ISNUMBER(Gesamtpunkte[[#This Row],[Matr.-Nr.]])),"NEIN","JA") -> JA | N11: 25 | O11: 0 | P11: =O11/$O$25 -> 0 | R11: 25 | S11: 0 | T11: =S11/$S$16 -> #DIV/0! | U11: 0 | V11: =U11/$U$16 -> 0
A12: ='2a.Detailpunkte'!D10 -> 3300459 | B12: ='2a.Detailpunkte'!E10 -> Stud08 | C12: ='2a.Detailpunkte'!F10 -> Pseudo | D12: =INDEX('3. Notenszenarien'!$I$6:$I$350,MATCH(Gesamtpunkte[[#This Row],[Matr.-Nr.]],'3. Notenszenarien'!$A$6:$A$1048576,0)) -> 2.3 | E12: =ROUNDUP(INDEX('2a.Detailpunkte'!$A$4:$A$352,MATCH('2. Punkte_Prüfung'!A12,'2a.Detailpunkte'!$D$4:$D$352,0),1)/5,1)*5 -> 71.5 | F12: =Gesamtpunkte[[#This Row],[Gesamtpunkte ]]/$E$4 -> 0.79444444 | G12: =INDEX('2a.Detailpunkte'!$B$4:$B$352,MATCH('2. Punkte_Prüfung'!A12,'2a.Detailpunkte'!$D$4:$D$352,0),1) -> 72 | H12: =INDEX('2a.Detailpunkte'!$C$4:$C$352,MATCH('2. Punkte_Prüfung'!A12,'2a.Detailpunkte'!$D$4:$D$352,0),1) -> 0 | I12: =Gesamtpunkte[[#This Row],[Punkte F]]/$G$4 -> 1.6 | J12: =Gesamtpunkte[[#This Row],[Punkte I]]/$H$4 -> 0 | K12: =IF(AND(ISNA(MATCH(Gesamtpunkte[[#This Row],[Matr.-Nr.]],'4. Noteneintrag'!$C$11:$C$1048576,0)),ISNUMBER(Gesamtpunkte[[#This Row],[Matr.-Nr.]])),"NEIN","JA") -> JA | N12: 30 | O12: 0 | P12: =O12/$O$25 -> 0 | R12: 30 | S12: 0 | T12: =S12/$S$16 -> #DIV/0! | U12: 0 | V12: =U12/$U$16 -> 0
A13: ='2a.Detailpunkte'!D11 -> 3513448 | B13: ='2a.Detailpunkte'!E11 -> Stud25 | C13: ='2a.Detailpunkte'!F11 -> Pseudo | D13: =INDEX('3. Notenszenarien'!$I$6:$I$350,MATCH(Gesamtpunkte[[#This Row],[Matr.-Nr.]],'3. Notenszenarien'!$A$6:$A$1048576,0)) -> 1.7 | E13: =ROUNDUP(INDEX('2a.Detailpunkte'!$A$4:$A$352,MATCH('2. Punkte_Prüfung'!A13,'2a.Detailpunkte'!$D$4:$D$352,0),1)/5,1)*5 -> 77 | F13: =Gesamtpunkte[[#This Row],[Gesamtpunkte ]]/$E$4 -> 0.85555556 | G13: =INDEX('2a.Detailpunkte'!$B$4:$B$352,MATCH('2. Punkte_Prüfung'!A13,'2a.Detailpunkte'!$D$4:$D$352,0),1) -> 77 | H13: =INDEX('2a.Detailpunkte'!$C$4:$C$352,MATCH('2. Punkte_Prüfung'!A13,'2a.Detailpunkte'!$D$4:$D$352,0),1) -> 0 | I13: =Gesamtpunkte[[#This Row],[Punkte F]]/$G$4 -> 1.7111111 | J13: =Gesamtpunkte[[#This Row],[Punkte I]]/$H$4 -> 0 | K13: =IF(AND(ISNA(MATCH(Gesamtpunkte[[#This Row],[Matr.-Nr.]],'4. Noteneintrag'!$C$11:$C$1048576,0)),ISNUMBER(Gesamtpunkte[[#This Row],[Matr.-Nr.]])),"NEIN","JA") -> JA | N13: 35 | O13: 0 | P13: =O13/$O$25 -> 0 | R13: 35 | S13: 0 | T13: =S13/$S$16 -> #DIV/0! | U13: 0 | V13: =U13/$U$16 -> 0
A14: ='2a.Detailpunkte'!D12 -> 3314377 | B14: ='2a.Detailpunkte'!E12 -> Stud10 | C14: ='2a.Detailpunkte'!F12 -> Pseudo | D14: =INDEX('3. Notenszenarien'!$I$6:$I$350,MATCH(Gesamtpunkte[[#This Row],[Matr.-Nr.]],'3. Notenszenarien'!$A$6:$A$1048576,0)) -> 1.7 | E14: =ROUNDUP(INDEX('2a.Detailpunkte'!$A$4:$A$352,MATCH('2. Punkte_Prüfung'!A14,'2a.Detailpunkte'!$D$4:$D$352,0),1)/5,1)*5 -> 77 | F14: =Gesamtpunkte[[#This Row],[Gesamtpunkte ]]/$E$4 -> 0.85555556 | G14: =INDEX('2a.Detailpunkte'!$B$4:$B$352,MATCH('2. Punkte_Prüfung'!A14,'2a.Detailpunkte'!$D$4:$D$352,0),1) -> 77 | H14: =INDEX('2a.Detailpunkte'!$C$4:$C$352,MATCH('2. Punkte_Prüfung'!A14,'2a.Detailpunkte'!$D$4:$D$352,0),1) -> 0 | I14: =Gesamtpunkte[[#This Row],[Punkte F]]/$G$4 -> 1.7111111 | J14: =Gesamtpunkte[[#This Row],[Punkte I]]/$H$4 -> 0 | K14: =IF(AND(ISNA(MATCH(Gesamtpunkte[[#This Row],[Matr.-Nr.]],'4. Noteneintrag'!$C$11:$C$1048576,0)),ISNUMBER(Gesamtpunkte[[#This Row],[Matr.-Nr.]])),"NEIN","JA") -> JA | N14: 40 | O14: 0 | P14: =O14/$O$25 -> 0 | R14: 40 | S14: 0 | T14: =S14/$S$16 -> #DIV/0! | U14: 0 | V14: =U14/$U$16 -> 0
A15: ='2a.Detailpunkte'!D13 -> 3478653 | B15: ='2a.Detailpunkte'!E13 -> Stud21 | C15: ='2a.Detailpunkte'!F13 -> Pseudo | D15: =INDEX('3. Notenszenarien'!$I$6:$I$350,MATCH(Gesamtpunkte[[#This Row],[Matr.-Nr.]],'3. Notenszenarien'!$A$6:$A$1048576,0)) -> 1.3 | E15: =ROUNDUP(INDEX('2a.Detailpunkte'!$A$4:$A$352,MATCH('2. Punkte_Prüfung'!A15,'2a.Detailpunkte'!$D$4:$D$352,0),1)/5,1)*5 -> 82.5 | F15: =Gesamtpunkte[[#This Row],[Gesamtpunkte ]]/$E$4 -> 0.91666667 | G15: =INDEX('2a.Detailpunkte'!$B$4:$B$352,MATCH('2. Punkte_Prüfung'!A15,'2a.Detailpunkte'!$D$4:$D$352,0),1) -> 85.5 | H15: =INDEX('2a.Detailpunkte'!$C$4:$C$352,MATCH('2. Punkte_Prüfung'!A15,'2a.Detailpunkte'!$D$4:$D$352,0),1) -> 0 | I15: =Gesamtpunkte[[#This Row],[Punkte F]]/$G$4 -> 1.9 | J15: =Gesamtpunkte[[#This Row],[Punkte I]]/$H$4 -> 0 | K15: =IF(AND(ISNA(MATCH(Gesamtpunkte[[#This Row],[Matr.-Nr.]],'4. Noteneintrag'!$C$11:$C$1048576,0)),ISNUMBER(Gesamtpunkte[[#This Row],[Matr.-Nr.]])),"NEIN","JA") -> JA | N15: 45 | O15: 0 | P15: =O15/$O$25 -> 0 | R15: 45 | S15: 0 | T15: =S15/$S$16 -> #DIV/0! | U15: 0 | V15: =U15/$U$16 -> 0
A16: ='2a.Detailpunkte'!D14 -> 3478426 | B16: ='2a.Detailpunkte'!E14 -> Stud20 | C16: ='2a.Detailpunkte'!F14 -> Pseudo | D16: =INDEX('3. Notenszenarien'!$I$6:$I$350,MATCH(Gesamtpunkte[[#This Row],[Matr.-Nr.]],'3. Notenszenarien'!$A$6:$A$1048576,0)) -> 1.7 | E16: =ROUNDUP(INDEX('2a.Detailpunkte'!$A$4:$A$352,MATCH('2. Punkte_Prüfung'!A16,'2a.Detailpunkte'!$D$4:$D$352,0),1)/5,1)*5 -> 76.5 | F16: =Gesamtpunkte[[#This Row],[Gesamtpunkte ]]/$E$4 -> 0.85 | G16: =INDEX('2a.Detailpunkte'!$B$4:$B$352,MATCH('2. Punkte_Prüfung'!A16,'2a.Detailpunkte'!$D$4:$D$352,0),1) -> 76.5 | H16: =INDEX('2a.Detailpunkte'!$C$4:$C$352,MATCH('2. Punkte_Prüfung'!A16,'2a.Detailpunkte'!$D$4:$D$352,0),1) -> 0 | I16: =Gesamtpunkte[[#This Row],[Punkte F]]/$G$4 -> 1.7 | J16: =Gesamtpunkte[[#This Row],[Punkte I]]/$H$4 -> 0 | K16: =IF(AND(ISNA(MATCH(Gesamtpunkte[[#This Row],[Matr.-Nr.]],'4. Noteneintrag'!$C$11:$C$1048576,0)),ISNUMBER(Gesamtpunkte[[#This Row],[Matr.-Nr.]])),"NEIN","JA") -> JA | N16: 50 | O16: 0 | P16: =O16/$O$25 -> 0 | R16: Summe | S16: =SUM(S6:S15) -> 0 | T16: =SUM(T6:T15) -> #DIV/0! | U16: =SUM(U6:U15) -> 28 | V16: =SUM(V6:V15) -> 1
A17: ='2a.Detailpunkte'!D15 -> 3202847 | B17: ='2a.Detailpunkte'!E15 -> Stud02 | C17: ='2a.Detailpunkte'!F15 -> Pseudo | D17: =INDEX('3. Notenszenarien'!$I$6:$I$350,MATCH(Gesamtpunkte[[#This Row],[Matr.-Nr.]],'3. Notenszenarien'!$A$6:$A$1048576,0)) -> 2 | E17: =ROUNDUP(INDEX('2a.Detailpunkte'!$A$4:$A$352,MATCH('2. Punkte_Prüfung'!A17,'2a.Detailpunkte'!$D$4:$D$352,0),1)/5,1)*5 -> 75.5 | F17: =Gesamtpunkte[[#This Row],[Gesamtpunkte ]]/$E$4 -> 0.83888889 | G17: =INDEX('2a.Detailpunkte'!$B$4:$B$352,MATCH('2. Punkte_Prüfung'!A17,'2a.Detailpunkte'!$D$4:$D$352,0),1) -> 75.5 | H17: =INDEX('2a.Detailpunkte'!$C$4:$C$352,MATCH('2. Punkte_Prüfung'!A17,'2a.Detailpunkte'!$D$4:$D$352,0),1) -> 0 | I17: =Gesamtpunkte[[#This Row],[Punkte F]]/$G$4 -> 1.6777778 | J17: =Gesamtpunkte[[#This Row],[Punkte I]]/$H$4 -> 0 | K17: =IF(AND(ISNA(MATCH(Gesamtpunkte[[#This Row],[Matr.-Nr.]],'4. Noteneintrag'!$C$11:$C$1048576,0)),ISNUMBER(Gesamtpunkte[[#This Row],[Matr.-Nr.]])),"NEIN","JA") -> JA | N17: 55 | O17: 0 | P17: =O17/$O$25 -> 0
A18: ='2a.Detailpunkte'!D16 -> 3472086 | B18: ='2a.Detailpunkte'!E16 -> Stud15 | C18: ='2a.Detailpunkte'!F16 -> Pseudo | D18: =INDEX('3. Notenszenarien'!$I$6:$I$350,MATCH(Gesamtpunkte[[#This Row],[Matr.-Nr.]],'3. Notenszenarien'!$A$6:$A$1048576,0)) -> 2.3 | E18: =ROUNDUP(INDEX('2a.Detailpunkte'!$A$4:$A$352,MATCH('2. Punkte_Prüfung'!A18,'2a.Detailpunkte'!$D$4:$D$352,0),1)/5,1)*5 -> 71 | F18: =Gesamtpunkte[[#This Row],[Gesamtpunkte ]]/$E$4 -> 0.78888889 | G18: =INDEX('2a.Detailpunkte'!$B$4:$B$352,MATCH('2. Punkte_Prüfung'!A18,'2a.Detailpunkte'!$D$4:$D$352,0),1) -> 71 | H18: =INDEX('2a.Detailpunkte'!$C$4:$C$352,MATCH('2. Punkte_Prüfung'!A18,'2a.Detailpunkte'!$D$4:$D$352,0),1) -> 0 | I18: =Gesamtpunkte[[#This Row],[Punkte F]]/$G$4 -> 1.5777778 | J18: =Gesamtpunkte[[#This Row],[Punkte I]]/$H$4 -> 0 | K18: =IF(AND(ISNA(MATCH(Gesamtpunkte[[#This Row],[Matr.-Nr.]],'4. Noteneintrag'!$C$11:$C$1048576,0)),ISNUMBER(Gesamtpunkte[[#This Row],[Matr.-Nr.]])),"NEIN","JA") -> JA | N18: 60 | O18: 0 | P18: =O18/$O$25 -> 0
A19: ='2a.Detailpunkte'!D17 -> 3226049 | B19: ='2a.Detailpunkte'!E17 -> Stud03 | C19: ='2a.Detailpunkte'!F17 -> Pseudo | D19: =INDEX('3. Notenszenarien'!$I$6:$I$350,MATCH(Gesamtpunkte[[#This Row],[Matr.-Nr.]],'3. Notenszenarien'!$A$6:$A$1048576,0)) -> 1 | E19: =ROUNDUP(INDEX('2a.Detailpunkte'!$A$4:$A$352,MATCH('2. Punkte_Prüfung'!A19,'2a.Detailpunkte'!$D$4:$D$352,0),1)/5,1)*5 -> 87 | F19: =Gesamtpunkte[[#This Row],[Gesamtpunkte ]]/$E$4 -> 0.96666667 | G19: =INDEX('2a.Detailpunkte'!$B$4:$B$352,MATCH('2. Punkte_Prüfung'!A19,'2a.Detailpunkte'!$D$4:$D$352,0),1) -> 87 | H19: =INDEX('2a.Detailpunkte'!$C$4:$C$352,MATCH('2. Punkte_Prüfung'!A19,'2a.Detailpunkte'!$D$4:$D$352,0),1) -> 0 | I19: =Gesamtpunkte[[#This Row],[Punkte F]]/$G$4 -> 1.9333333 | J19: =Gesamtpunkte[[#This Row],[Punkte I]]/$H$4 -> 0 | K19: =IF(AND(ISNA(MATCH(Gesamtpunkte[[#This Row],[Matr.-Nr.]],'4. Noteneintrag'!$C$11:$C$1048576,0)),ISNUMBER(Gesamtpunkte[[#This Row],[Matr.-Nr.]])),"NEIN","JA") -> JA | N19: 65 | O19: 1 | P19: =O19/$O$25 -> 0.035714286
A20: ='2a.Detailpunkte'!D18 -> 3483130 | B20: ='2a.Detailpunkte'!E18 -> Stud22 | C20: ='2a.Detailpunkte'!F18 -> Pseudo | D20: =INDEX('3. Notenszenarien'!$I$6:$I$350,MATCH(Gesamtpunkte[[#This Row],[Matr.-Nr.]],'3. Notenszenarien'!$A$6:$A$1048576,0)) -> 2 | E20: =ROUNDUP(INDEX('2a.Detailpunkte'!$A$4:$A$352,MATCH('2. Punkte_Prüfung'!A20,'2a.Detailpunkte'!$D$4:$D$352,0),1)/5,1)*5 -> 72 | F20: =Gesamtpunkte[[#This Row],[Gesamtpunkte ]]/$E$4 -> 0.8 | G20: =INDEX('2a.Detailpunkte'!$B$4:$B$352,MATCH('2. Punkte_Prüfung'!A20,'2a.Detailpunkte'!$D$4:$D$352,0),1) -> 72 | H20: =INDEX('2a.Detailpunkte'!$C$4:$C$352,MATCH('2. Punkte_Prüfung'!A20,'2a.Detailpunkte'!$D$4:$D$352,0),1) -> 0 | I20: =Gesamtpunkte[[#This Row],[Punkte F]]/$G$4 -> 1.6 | J20: =Gesamtpunkte[[#This Row],[Punkte I]]/$H$4 -> 0 | K20: =IF(AND(ISNA(MATCH(Gesamtpunkte[[#This Row],[Matr.-Nr.]],'4. Noteneintrag'!$C$11:$C$1048576,0)),ISNUMBER(Gesamtpunkte[[#This Row],[Matr.-Nr.]])),"NEIN","JA") -> JA | N20: 70 | O20: 2 | P20: =O20/$O$25 -> 0.071428571
A21: ='2a.Detailpunkte'!D19 -> 3298408 | B21: ='2a.Detailpunkte'!E19 -> Stud07 | C21: ='2a.Detailpunkte'!F19 -> Pseudo | D21: =INDEX('3. Notenszenarien'!$I$6:$I$350,MATCH(Gesamtpunkte[[#This Row],[Matr.-Nr.]],'3. Notenszenarien'!$A$6:$A$1048576,0)) -> 2 | E21: =ROUNDUP(INDEX('2a.Detailpunkte'!$A$4:$A$352,MATCH('2. Punkte_Prüfung'!A21,'2a.Detailpunkte'!$D$4:$D$352,0),1)/5,1)*5 -> 76 | F21: =Gesamtpunkte[[#This Row],[Gesamtpunkte ]]/$E$4 -> 0.84444444 | G21: =INDEX('2a.Detailpunkte'!$B$4:$B$352,MATCH('2. Punkte_Prüfung'!A21,'2a.Detailpunkte'!$D$4:$D$352,0),1) -> 76.5 | H21: =INDEX('2a.Detailpunkte'!$C$4:$C$352,MATCH('2. Punkte_Prüfung'!A21,'2a.Detailpunkte'!$D$4:$D$352,0),1) -> 0 | I21: =Gesamtpunkte[[#This Row],[Punkte F]]/$G$4 -> 1.7 | J21: =Gesamtpunkte[[#This Row],[Punkte I]]/$H$4 -> 0 | K21: =IF(AND(ISNA(MATCH(Gesamtpunkte[[#This Row],[Matr.-Nr.]],'4. Noteneintrag'!$C$11:$C$1048576,0)),ISNUMBER(Gesamtpunkte[[#This Row],[Matr.-Nr.]])),"NEIN","JA") -> JA | N21: 75 | O21: 10 | P21: =O21/$O$25 -> 0.35714286
A22: ='2a.Detailpunkte'!D20 -> 3489059 | B22: ='2a.Detailpunkte'!E20 -> Stud23 | C22: ='2a.Detailpunkte'!F20 -> Pseudo | D22: =INDEX('3. Notenszenarien'!$I$6:$I$350,MATCH(Gesamtpunkte[[#This Row],[Matr.-Nr.]],'3. Notenszenarien'!$A$6:$A$1048576,0)) -> 1.7 | E22: =ROUNDUP(INDEX('2a.Detailpunkte'!$A$4:$A$352,MATCH('2. Punkte_Prüfung'!A22,'2a.Detailpunkte'!$D$4:$D$352,0),1)/5,1)*5 -> 76.5 | F22: =Gesamtpunkte[[#This Row],[Gesamtpunkte ]]/$E$4 -> 0.85 | G22: =INDEX('2a.Detailpunkte'!$B$4:$B$352,MATCH('2. Punkte_Prüfung'!A22,'2a.Detailpunkte'!$D$4:$D$352,0),1) -> 76.33 | H22: =INDEX('2a.Detailpunkte'!$C$4:$C$352,MATCH('2. Punkte_Prüfung'!A22,'2a.Detailpunkte'!$D$4:$D$352,0),1) -> 0 | I22: =Gesamtpunkte[[#This Row],[Punkte F]]/$G$4 -> 1.6962222 | J22: =Gesamtpunkte[[#This Row],[Punkte I]]/$H$4 -> 0 | K22: =IF(AND(ISNA(MATCH(Gesamtpunkte[[#This Row],[Matr.-Nr.]],'4. Noteneintrag'!$C$11:$C$1048576,0)),ISNUMBER(Gesamtpunkte[[#This Row],[Matr.-Nr.]])),"NEIN","JA") -> JA | N22: 80 | O22: 9 | P22: =O22/$O$25 -> 0.32142857
A23: ='2a.Detailpunkte'!D21 -> 3273308 | B23: ='2a.Detailpunkte'!E21 -> Stud05 | C23: ='2a.Detailpunkte'!F21 -> Pseudo | D23: =INDEX('3. Notenszenarien'!$I$6:$I$350,MATCH(Gesamtpunkte[[#This Row],[Matr.-Nr.]],'3. Notenszenarien'!$A$6:$A$1048576,0)) -> 2 | E23: =ROUNDUP(INDEX('2a.Detailpunkte'!$A$4:$A$352,MATCH('2. Punkte_Prüfung'!A23,'2a.Detailpunkte'!$D$4:$D$352,0),1)/5,1)*5 -> 72 | F23: =Gesamtpunkte[[#This Row],[Gesamtpunkte ]]/$E$4 -> 0.8 | G23: =INDEX('2a.Detailpunkte'!$B$4:$B$352,MATCH('2. Punkte_Prüfung'!A23,'2a.Detailpunkte'!$D$4:$D$352,0),1) -> 71.83 | H23: =INDEX('2a.Detailpunkte'!$C$4:$C$352,MATCH('2. Punkte_Prüfung'!A23,'2a.Detailpunkte'!$D$4:$D$352,0),1) -> 0 | I23: =Gesamtpunkte[[#This Row],[Punkte F]]/$G$4 -> 1.5962222 | J23: =Gesamtpunkte[[#This Row],[Punkte I]]/$H$4 -> 0 | K23: =IF(AND(ISNA(MATCH(Gesamtpunkte[[#This Row],[Matr.-Nr.]],'4. Noteneintrag'!$C$11:$C$1048576,0)),ISNUMBER(Gesamtpunkte[[#This Row],[Matr.-Nr.]])),"NEIN","JA") -> JA | N23: 85 | O23: 5 | P23: =O23/$O$25 -> 0.17857143
A24: ='2a.Detailpunkte'!D22 -> 3361157 | B24: ='2a.Detailpunkte'!E22 -> Stud12 | C24: ='2a.Detailpunkte'!F22 -> Pseudo | D24: =INDEX('3. Notenszenarien'!$I$6:$I$350,MATCH(Gesamtpunkte[[#This Row],[Matr.-Nr.]],'3. Notenszenarien'!$A$6:$A$1048576,0)) -> 1.3 | E24: =ROUNDUP(INDEX('2a.Detailpunkte'!$A$4:$A$352,MATCH('2. Punkte_Prüfung'!A24,'2a.Detailpunkte'!$D$4:$D$352,0),1)/5,1)*5 -> 83 | F24: =Gesamtpunkte[[#This Row],[Gesamtpunkte ]]/$E$4 -> 0.92222222 | G24: =INDEX('2a.Detailpunkte'!$B$4:$B$352,MATCH('2. Punkte_Prüfung'!A24,'2a.Detailpunkte'!$D$4:$D$352,0),1) -> 83 | H24: =INDEX('2a.Detailpunkte'!$C$4:$C$352,MATCH('2. Punkte_Prüfung'!A24,'2a.Detailpunkte'!$D$4:$D$352,0),1) -> 0 | I24: =Gesamtpunkte[[#This Row],[Punkte F]]/$G$4 -> 1.8444444 | J24: =Gesamtpunkte[[#This Row],[Punkte I]]/$H$4 -> 0 | K24: =IF(AND(ISNA(MATCH(Gesamtpunkte[[#This Row],[Matr.-Nr.]],'4. Noteneintrag'!$C$11:$C$1048576,0)),ISNUMBER(Gesamtpunkte[[#This Row],[Matr.-Nr.]])),"NEIN","JA") -> JA | N24: 90 | O24: 1 | P24: =O24/$O$25 -> 0.035714286
A25: ='2a.Detailpunkte'!D23 -> 3475876 | B25: ='2a.Detailpunkte'!E23 -> Stud18 | C25: ='2a.Detailpunkte'!F23 -> Pseudo | D25: =INDEX('3. Notenszenarien'!$I$6:$I$350,MATCH(Gesamtpunkte[[#This Row],[Matr.-Nr.]],'3. Notenszenarien'!$A$6:$A$1048576,0)) -> 1.3 | E25: =ROUNDUP(INDEX('2a.Detailpunkte'!$A$4:$A$352,MATCH('2. Punkte_Prüfung'!A25,'2a.Detailpunkte'!$D$4:$D$352,0),1)/5,1)*5 -> 83 | F25: =Gesamtpunkte[[#This Row],[Gesamtpunkte ]]/$E$4 -> 0.92222222 | G25: =INDEX('2a.Detailpunkte'!$B$4:$B$352,MATCH('2. Punkte_Prüfung'!A25,'2a.Detailpunkte'!$D$4:$D$352,0),1) -> 83 | H25: =INDEX('2a.Detailpunkte'!$C$4:$C$352,MATCH('2. Punkte_Prüfung'!A25,'2a.Detailpunkte'!$D$4:$D$352,0),1) -> 0 | I25: =Gesamtpunkte[[#This Row],[Punkte F]]/$G$4 -> 1.8444444 | J25: =Gesamtpunkte[[#This Row],[Punkte I]]/$H$4 -> 0 | K25: =IF(AND(ISNA(MATCH(Gesamtpunkte[[#This Row],[Matr.-Nr.]],'4. Noteneintrag'!$C$11:$C$1048576,0)),ISNUMBER(Gesamtpunkte[[#This Row],[Matr.-Nr.]])),"NEIN","JA") -> JA | N25: Summe | O25: =SUM(O6:O24) -> 28 | P25: =SUM(P6:P24) -> 1
A26: ='2a.Detailpunkte'!D24 -> 3513589 | B26: ='2a.Detailpunkte'!E24 -> Stud26 | C26: ='2a.Detailpunkte'!F24 -> Pseudo | D26: =INDEX('3. Notenszenarien'!$I$6:$I$350,MATCH(Gesamtpunkte[[#This Row],[Matr.-Nr.]],'3. Notenszenarien'!$A$6:$A$1048576,0)) -> 2 | E26: =ROUNDUP(INDEX('2a.Detailpunkte'!$A$4:$A$352,MATCH('2. Punkte_Prüfung'!A26,'2a.Detailpunkte'!$D$4:$D$352,0),1)/5,1)*5 -> 73.5 | F26: =Gesamtpunkte[[#This Row],[Gesamtpunkte ]]/$E$4 -> 0.81666667 | G26: =INDEX('2a.Detailpunkte'!$B$4:$B$352,MATCH('2. Punkte_Prüfung'!A26,'2a.Detailpunkte'!$D$4:$D$352,0),1) -> 73.5 | H26: =INDEX('2a.Detailpunkte'!$C$4:$C$352,MATCH('2. Punkte_Prüfung'!A26,'2a.Detailpunkte'!$D$4:$D$352,0),1) -> 0 | I26: =Gesamtpunkte[[#This Row],[Punkte F]]/$G$4 -> 1.6333333 | J26: =Gesamtpunkte[[#This Row],[Punkte I]]/$H$4 -> 0 | K26: =IF(AND(ISNA(MATCH(Gesamtpunkte[[#This Row],[Matr.-Nr.]],'4. Noteneintrag'!$C$11:$C$1048576,0)),ISNUMBER(Gesamtpunkte[[#This Row],[Matr.-Nr.]])),"NEIN","JA") -> JA
A27: ='2a.Detailpunkte'!D25 -> 3173903 | B27: ='2a.Detailpunkte'!E25 -> Stud01 | C27: ='2a.Detailpunkte'!F25 -> Pseudo | D27: =INDEX('3. Notenszenarien'!$I$6:$I$350,MATCH(Gesamtpunkte[[#This Row],[Matr.-Nr.]],'3. Notenszenarien'!$A$6:$A$1048576,0)) -> 1.7 | E27: =ROUNDUP(INDEX('2a.Detailpunkte'!$A$4:$A$352,MATCH('2. Punkte_Prüfung'!A27,'2a.Detailpunkte'!$D$4:$D$352,0),1)/5,1)*5 -> 77.5 | F27: =Gesamtpunkte[[#This Row],[Gesamtpunkte ]]/$E$4 -> 0.86111111 | G27: =INDEX('2a.Detailpunkte'!$B$4:$B$352,MATCH('2. Punkte_Prüfung'!A27,'2a.Detailpunkte'!$D$4:$D$352,0),1) -> 77.5 | H27: =INDEX('2a.Detailpunkte'!$C$4:$C$352,MATCH('2. Punkte_Prüfung'!A27,'2a.Detailpunkte'!$D$4:$D$352,0),1) -> 0 | I27: =Gesamtpunkte[[#This Row],[Punkte F]]/$G$4 -> 1.7222222 | J27: =Gesamtpunkte[[#This Row],[Punkte I]]/$H$4 -> 0 | K27: =IF(AND(ISNA(MATCH(Gesamtpunkte[[#This Row],[Matr.-Nr.]],'4. Noteneintrag'!$C$11:$C$1048576,0)),ISNUMBER(Gesamtpunkte[[#This Row],[Matr.-Nr.]])),"NEIN","JA") -> JA
A28: ='2a.Detailpunkte'!D26 -> 3312357 | B28: ='2a.Detailpunkte'!E26 -> Stud09 | C28: ='2a.Detailpunkte'!F26 -> Pseudo | D28: =INDEX('3. Notenszenarien'!$I$6:$I$350,MATCH(Gesamtpunkte[[#This Row],[Matr.-Nr.]],'3. Notenszenarien'!$A$6:$A$1048576,0)) -> 1.3 | E28: =ROUNDUP(INDEX('2a.Detailpunkte'!$A$4:$A$352,MATCH('2. Punkte_Prüfung'!A28,'2a.Detailpunkte'!$D$4:$D$352,0),1)/5,1)*5 -> 84 | F28: =Gesamtpunkte[[#This Row],[Gesamtpunkte ]]/$E$4 -> 0.93333333 | G28: =INDEX('2a.Detailpunkte'!$B$4:$B$352,MATCH('2. Punkte_Prüfung'!A28,'2a.Detailpunkte'!$D$4:$D$352,0),1) -> 84 | H28: =INDEX('2a.Detailpunkte'!$C$4:$C$352,MATCH('2. Punkte_Prüfung'!A28,'2a.Detailpunkte'!$D$4:$D$352,0),1) -> 0 | I28: =Gesamtpunkte[[#This Row],[Punkte F]]/$G$4 -> 1.8666667 | J28: =Gesamtpunkte[[#This Row],[Punkte I]]/$H$4 -> 0 | K28: =IF(AND(ISNA(MATCH(Gesamtpunkte[[#This Row],[Matr.-Nr.]],'4. Noteneintrag'!$C$11:$C$1048576,0)),ISNUMBER(Gesamtpunkte[[#This Row],[Matr.-Nr.]])),"NEIN","JA") -> JA
A29: ='2a.Detailpunkte'!D27 -> 3269604 | B29: ='2a.Detailpunkte'!E27 -> Stud04 | C29: ='2a.Detailpunkte'!F27 -> Pseudo | D29: =INDEX('3. Notenszenarien'!$I$6:$I$350,MATCH(Gesamtpunkte[[#This Row],[Matr.-Nr.]],'3. Notenszenarien'!$A$6:$A$1048576,0)) -> 1.3 | E29: =ROUNDUP(INDEX('2a.Detailpunkte'!$A$4:$A$352,MATCH('2. Punkte_Prüfung'!A29,'2a.Detailpunkte'!$D$4:$D$352,0),1)/5,1)*5 -> 84.5 | F29: =Gesamtpunkte[[#This Row],[Gesamtpunkte ]]/$E$4 -> 0.93888889 | G29: =INDEX('2a.Detailpunkte'!$B$4:$B$352,MATCH('2. Punkte_Prüfung'!A29,'2a.Detailpunkte'!$D$4:$D$352,0),1) -> 84.5 | H29: =INDEX('2a.Detailpunkte'!$C$4:$C$352,MATCH('2. Punkte_Prüfung'!A29,'2a.Detailpunkte'!$D$4:$D$352,0),1) -> 0 | I29: =Gesamtpunkte[[#This Row],[Punkte F]]/$G$4 -> 1.8777778 | J29: =Gesamtpunkte[[#This Row],[Punkte I]]/$H$4 -> 0 | K29: =IF(AND(ISNA(MATCH(Gesamtpunkte[[#This Row],[Matr.-Nr.]],'4. Noteneintrag'!$C$11:$C$1048576,0)),ISNUMBER(Gesamtpunkte[[#This Row],[Matr.-Nr.]])),"NEIN","JA") -> JA
A30: ='2a.Detailpunkte'!D28 -> 3274772 | B30: ='2a.Detailpunkte'!E28 -> Stud06 | C30: ='2a.Detailpunkte'!F28 -> Pseudo | D30: =INDEX('3. Notenszenarien'!$I$6:$I$350,MATCH(Gesamtpunkte[[#This Row],[Matr.-Nr.]],'3. Notenszenarien'!$A$6:$A$1048576,0)) -> 2.3 | E30: =ROUNDUP(INDEX('2a.Detailpunkte'!$A$4:$A$352,MATCH('2. Punkte_Prüfung'!A30,'2a.Detailpunkte'!$D$4:$D$352,0),1)/5,1)*5 -> 70.5 | F30: =Gesamtpunkte[[#This Row],[Gesamtpunkte ]]/$E$4 -> 0.78333333 | G30: =INDEX('2a.Detailpunkte'!$B$4:$B$352,MATCH('2. Punkte_Prüfung'!A30,'2a.Detailpunkte'!$D$4:$D$352,0),1) -> 70.33 | H30: =INDEX('2a.Detailpunkte'!$C$4:$C$352,MATCH('2. Punkte_Prüfung'!A30,'2a.Detailpunkte'!$D$4:$D$352,0),1) -> 0 | I30: =Gesamtpunkte[[#This Row],[Punkte F]]/$G$4 -> 1.5628889 | J30: =Gesamtpunkte[[#This Row],[Punkte I]]/$H$4 -> 0 | K30: =IF(AND(ISNA(MATCH(Gesamtpunkte[[#This Row],[Matr.-Nr.]],'4. Noteneintrag'!$C$11:$C$1048576,0)),ISNUMBER(Gesamtpunkte[[#This Row],[Matr.-Nr.]])),"NEIN","JA") -> JA
A31: ='2a.Detailpunkte'!D29 -> 3514106 | B31: ='2a.Detailpunkte'!E29 -> Stud27 | C31: ='2a.Detailpunkte'!F29 -> Pseudo | D31: =INDEX('3. Notenszenarien'!$I$6:$I$350,MATCH(Gesamtpunkte[[#This Row],[Matr.-Nr.]],'3. Notenszenarien'!$A$6:$A$1048576,0)) -> 3 | E31: =ROUNDUP(INDEX('2a.Detailpunkte'!$A$4:$A$352,MATCH('2. Punkte_Prüfung'!A31,'2a.Detailpunkte'!$D$4:$D$352,0),1)/5,1)*5 -> 61.5 | F31: =Gesamtpunkte[[#This Row],[Gesamtpunkte ]]/$E$4 -> 0.68333333 | G31: =INDEX('2a.Detailpunkte'!$B$4:$B$352,MATCH('2. Punkte_Prüfung'!A31,'2a.Detailpunkte'!$D$4:$D$352,0),1) -> 61.33 | H31: =INDEX('2a.Detailpunkte'!$C$4:$C$352,MATCH('2. Punkte_Prüfung'!A31,'2a.Detailpunkte'!$D$4:$D$352,0),1) -> 0 | I31: =Gesamtpunkte[[#This Row],[Punkte F]]/$G$4 -> 1.3628889 | J31: =Gesamtpunkte[[#This Row],[Punkte I]]/$H$4 -> 0 | K31: =IF(AND(ISNA(MATCH(Gesamtpunkte[[#This Row],[Matr.-Nr.]],'4. Noteneintrag'!$C$11:$C$1048576,0)),ISNUMBER(Gesamtpunkte[[#This Row],[Matr.-Nr.]])),"NEIN","JA") -> JA
A32: ='2a.Detailpunkte'!D30 -> 3477713 | B32: ='2a.Detailpunkte'!E30 -> Stud19 | C32: ='2a.Detailpunkte'!F30 -> Pseudo | D32: =INDEX('3. Notenszenarien'!$I$6:$I$350,MATCH(Gesamtpunkte[[#This Row],[Matr.-Nr.]],'3. Notenszenarien'!$A$6:$A$1048576,0)) -> 2 | E32: =ROUNDUP(INDEX('2a.Detailpunkte'!$A$4:$A$352,MATCH('2. Punkte_Prüfung'!A32,'2a.Detailpunkte'!$D$4:$D$352,0),1)/5,1)*5 -> 74.5 | F32: =Gesamtpunkte[[#This Row],[Gesamtpunkte ]]/$E$4 -> 0.82777778 | G32: =INDEX('2a.Detailpunkte'!$B$4:$B$352,MATCH('2. Punkte_Prüfung'!A32,'2a.Detailpunkte'!$D$4:$D$352,0),1) -> 74.33 | H32: =INDEX('2a.Detailpunkte'!$C$4:$C$352,MATCH('2. Punkte_Prüfung'!A32,'2a.Detailpunkte'!$D$4:$D$352,0),1) -> 0 | I32: =Gesamtpunkte[[#This Row],[Punkte F]]/$G$4 -> 1.6517778 | J32: =Gesamtpunkte[[#This Row],[Punkte I]]/$H$4 -> 0 | K32: =IF(AND(ISNA(MATCH(Gesamtpunkte[[#This Row],[Matr.-Nr.]],'4. Noteneintrag'!$C$11:$C$1048576,0)),ISNUMBER(Gesamtpunkte[[#This Row],[Matr.-Nr.]])),"NEIN","JA") -> JA
A33: ='2a.Detailpunkte'!D31 -> 3491126 | B33: ='2a.Detailpunkte'!#REF! -> #REF! | C33: ='2a.Detailpunkte'!#REF! -> #REF! | D33: =INDEX('3. Notenszenarien'!$I$6:$I$350,MATCH(Gesamtpunkte[[#This Row],[Matr.-Nr.]],'3. Notenszenarien'!$A$6:$A$1048576,0)) -> 1.7 | E33: =ROUNDUP(INDEX('2a.Detailpunkte'!$A$4:$A$352,MATCH('2. Punkte_Prüfung'!A33,'2a.Detailpunkte'!$D$4:$D$352,0),1)/5,1)*5 -> 78 | F33: =Gesamtpunkte[[#This Row],[Gesamtpunkte ]]/$E$4 -> 0.86666667 | G33: =INDEX('2a.Detailpunkte'!$B$4:$B$352,MATCH('2. Punkte_Prüfung'!A33,'2a.Detailpunkte'!$D$4:$D$352,0),1) -> 78 | H33: =INDEX('2a.Detailpunkte'!$C$4:$C$352,MATCH('2. Punkte_Prüfung'!A33,'2a.Detailpunkte'!$D$4:$D$352,0),1) -> 0 | I33: =Gesamtpunkte[[#This Row],[Punkte F]]/$G$4 -> 1.7333333 | J33: =Gesamtpunkte[[#This Row],[Punkte I]]/$H$4 -> 0 | K33: =IF(AND(ISNA(MATCH(Gesamtpunkte[[#This Row],[Matr.-Nr.]],'4. Noteneintrag'!$C$11:$C$1048576,0)),ISNUMBER(Gesamtpunkte[[#This Row],[Matr.-Nr.]])),"NEIN","JA") -> JA
A34: ='2a.Detailpunkte'!D32 -> #N/A | B34: ='2a.Detailpunkte'!#REF! -> #REF! | C34: ='2a.Detailpunkte'!#REF! -> #REF! | D34: =INDEX('3. Notenszenarien'!$I$6:$I$350,MATCH(Gesamtpunkte[[#This Row],[Matr.-Nr.]],'3. Notenszenarien'!$A$6:$A$1048576,0)) -> #N/A | E34: =ROUNDUP(INDEX('2a.Detailpunkte'!$A$4:$A$352,MATCH('2. Punkte_Prüfung'!A34,'2a.Detailpunkte'!$D$4:$D$352,0),1)/5,1)*5 -> #N/A | F34: =Gesamtpunkte[[#This Row],[Gesamtpunkte ]]/$E$4 -> #N/A | G34: =INDEX('2a.Detailpunkte'!$B$4:$B$352,MATCH('2. Punkte_Prüfung'!A34,'2a.Detailpunkte'!$D$4:$D$352,0),1) -> #N/A | H34: =INDEX('2a.Detailpunkte'!$C$4:$C$352,MATCH('2. Punkte_Prüfung'!A34,'2a.Detailpunkte'!$D$4:$D$352,0),1) -> #N/A | I34: =Gesamtpunkte[[#This Row],[Punkte F]]/$G$4 -> #N/A | J34: =Gesamtpunkte[[#This Row],[Punkte I]]/$H$4 -> #N/A | K34: =IF(AND(ISNA(MATCH(Gesamtpunkte[[#This Row],[Matr.-Nr.]],'4. Noteneintrag'!$C$11:$C$1048576,0)),ISNUMBER(Gesamtpunkte[[#This Row],[Matr.-Nr.]])),"NEIN","JA") -> JA
A35: ='2a.Detailpunkte'!D33 -> #N/A | B35: ='2a.Detailpunkte'!#REF! -> #REF! | C35: ='2a.Detailpunkte'!#REF! -> #REF! | D35: =INDEX('3. Notenszenarien'!$I$6:$I$350,MATCH(Gesamtpunkte[[#This Row],[Matr.-Nr.]],'3. Notenszenarien'!$A$6:$A$1048576,0)) -> #N/A | E35: =ROUNDUP(INDEX('2a.Detailpunkte'!$A$4:$A$352,MATCH('2. Punkte_Prüfung'!A35,'2a.Detailpunkte'!$D$4:$D$352,0),1)/5,1)*5 -> #N/A | F35: =Gesamtpunkte[[#This Row],[Gesamtpunkte ]]/$E$4 -> #N/A | G35: =INDEX('2a.Detailpunkte'!$B$4:$B$352,MATCH('2. Punkte_Prüfung'!A35,'2a.Detailpunkte'!$D$4:$D$352,0),1) -> #N/A | H35: =INDEX('2a.Detailpunkte'!$C$4:$C$352,MATCH('2. Punkte_Prüfung'!A35,'2a.Detailpunkte'!$D$4:$D$352,0),1) -> #N/A | I35: =Gesamtpunkte[[#This Row],[Punkte F]]/$G$4 -> #N/A | J35: =Gesamtpunkte[[#This Row],[Punkte I]]/$H$4 -> #N/A | K35: =IF(AND(ISNA(MATCH(Gesamtpunkte[[#This Row],[Matr.-Nr.]],'4. Noteneintrag'!$C$11:$C$1048576,0)),ISNUMBER(Gesamtpunkte[[#This Row],[Matr.-Nr.]])),"NEIN","JA") -> JA
A36: ='2a.Detailpunkte'!D34 -> #N/A | B36: ='2a.Detailpunkte'!#REF! -> #REF! | C36: ='2a.Detailpunkte'!#REF! -> #REF! | D36: =INDEX('3. Notenszenarien'!$I$6:$I$350,MATCH(Gesamtpunkte[[#This Row],[Matr.-Nr.]],'3. Notenszenarien'!$A$6:$A$1048576,0)) -> #N/A | E36: =ROUNDUP(INDEX('2a.Detailpunkte'!$A$4:$A$352,MATCH('2. Punkte_Prüfung'!A36,'2a.Detailpunkte'!$D$4:$D$352,0),1)/5,1)*5 -> #N/A | F36: =Gesamtpunkte[[#This Row],[Gesamtpunkte ]]/$E$4 -> #N/A | G36: =INDEX('2a.Detailpunkte'!$B$4:$B$352,MATCH('2. Punkte_Prüfung'!A36,'2a.Detailpunkte'!$D$4:$D$352,0),1) -> #N/A | H36: =INDEX('2a.Detailpunkte'!$C$4:$C$352,MATCH('2. Punkte_Prüfung'!A36,'2a.Detailpunkte'!$D$4:$D$352,0),1) -> #N/A | I36: =Gesamtpunkte[[#This Row],[Punkte F]]/$G$4 -> #N/A | J36: =Gesamtpunkte[[#This Row],[Punkte I]]/$H$4 -> #N/A | K36: =IF(AND(ISNA(MATCH(Gesamtpunkte[[#This Row],[Matr.-Nr.]],'4. Noteneintrag'!$C$11:$C$1048576,0)),ISNUMBER(Gesamtpunkte[[#This Row],[Matr.-Nr.]])),"NEIN","JA") -> JA
A37: ='2a.Detailpunkte'!D35 -> #N/A | B37: ='2a.Detailpunkte'!#REF! -> #REF! | C37: ='2a.Detailpunkte'!#REF! -> #REF! | D37: =INDEX('3. Notenszenarien'!$I$6:$I$350,MATCH(Gesamtpunkte[[#This Row],[Matr.-Nr.]],'3. Notenszenarien'!$A$6:$A$1048576,0)) -> #N/A | E37: =ROUNDUP(INDEX('2a.Detailpunkte'!$A$4:$A$352,MATCH('2. Punkte_Prüfung'!A37,'2a.Detailpunkte'!$D$4:$D$352,0),1)/5,1)*5 -> #N/A | F37: =Gesamtpunkte[[#This Row],[Gesamtpunkte ]]/$E$4 -> #N/A | G37: =INDEX('2a.Detailpunkte'!$B$4:$B$352,MATCH('2. Punkte_Prüfung'!A37,'2a.Detailpunkte'!$D$4:$D$352,0),1) -> #N/A | H37: =INDEX('2a.Detailpunkte'!$C$4:$C$352,MATCH('2. Punkte_Prüfung'!A37,'2a.Detailpunkte'!$D$4:$D$352,0),1) -> #N/A | I37: =Gesamtpunkte[[#This Row],[Punkte F]]/$G$4 -> #N/A | J37: =Gesamtpunkte[[#This Row],[Punkte I]]/$H$4 -> #N/A | K37: =IF(AND(ISNA(MATCH(Gesamtpunkte[[#This Row],[Matr.-Nr.]],'4. Noteneintrag'!$C$11:$C$1048576,0)),ISNUMBER(Gesamtpunkte[[#This Row],[Matr.-Nr.]])),"NEIN","JA") -> JA
A38: ='2a.Detailpunkte'!D36 -> #N/A | B38: ='2a.Detailpunkte'!#REF! -> #REF! | C38: ='2a.Detailpunkte'!#REF! -> #REF! | D38: =INDEX('3. Notenszenarien'!$I$6:$I$350,MATCH(Gesamtpunkte[[#This Row],[Matr.-Nr.]],'3. Notenszenarien'!$A$6:$A$1048576,0)) -> #N/A | E38: =ROUNDUP(INDEX('2a.Detailpunkte'!$A$4:$A$352,MATCH('2. Punkte_Prüfung'!A38,'2a.Detailpunkte'!$D$4:$D$352,0),1)/5,1)*5 -> #N/A | F38: =Gesamtpunkte[[#This Row],[Gesamtpunkte ]]/$E$4 -> #N/A | G38: =INDEX('2a.Detailpunkte'!$B$4:$B$352,MATCH('2. Punkte_Prüfung'!A38,'2a.Detailpunkte'!$D$4:$D$352,0),1) -> #N/A | H38: =INDEX('2a.Detailpunkte'!$C$4:$C$352,MATCH('2. Punkte_Prüfung'!A38,'2a.Detailpunkte'!$D$4:$D$352,0),1) -> #N/A | I38: =Gesamtpunkte[[#This Row],[Punkte F]]/$G$4 -> #N/A | J38: =Gesamtpunkte[[#This Row],[Punkte I]]/$H$4 -> #N/A | K38: =IF(AND(ISNA(MATCH(Gesamtpunkte[[#This Row],[Matr.-Nr.]],'4. Noteneintrag'!$C$11:$C$1048576,0)),ISNUMBER(Gesamtpunkte[[#This Row],[Matr.-Nr.]])),"NEIN","JA") -> JA
A39: ='2a.Detailpunkte'!D37 -> #N/A | B39: ='2a.Detailpunkte'!#REF! -> #REF! | C39: ='2a.Detailpunkte'!#REF! -> #REF! | D39: =INDEX('3. Notenszenarien'!$I$6:$I$350,MATCH(Gesamtpunkte[[#This Row],[Matr.-Nr.]],'3. Notenszenarien'!$A$6:$A$1048576,0)) -> #N/A | E39: =ROUNDUP(INDEX('2a.Detailpunkte'!$A$4:$A$352,MATCH('2. Punkte_Prüfung'!A39,'2a.Detailpunkte'!$D$4:$D$352,0),1)/5,1)*5 -> #N/A | F39: =Gesamtpunkte[[#This Row],[Gesamtpunkte ]]/$E$4 -> #N/A | G39: =INDEX('2a.Detailpunkte'!$B$4:$B$352,MATCH('2. Punkte_Prüfung'!A39,'2a.Detailpunkte'!$D$4:$D$352,0),1) -> #N/A | H39: =INDEX('2a.Detailpunkte'!$C$4:$C$352,MATCH('2. Punkte_Prüfung'!A39,'2a.Detailpunkte'!$D$4:$D$352,0),1) -> #N/A | I39: =Gesamtpunkte[[#This Row],[Punkte F]]/$G$4 -> #N/A | J39: =Gesamtpunkte[[#This Row],[Punkte I]]/$H$4 -> #N/A | K39: =IF(AND(ISNA(MATCH(Gesamtpunkte[[#This Row],[Matr.-Nr.]],'4. Noteneintrag'!$C$11:$C$1048576,0)),ISNUMBER(Gesamtpunkte[[#This Row],[Matr.-Nr.]])),"NEIN","JA") -> JA
A40: ='2a.Detailpunkte'!D38 -> #N/A | B40: ='2a.Detailpunkte'!#REF! -> #REF! | C40: ='2a.Detailpunkte'!#REF! -> #REF! | D40: =INDEX('3. Notenszenarien'!$I$6:$I$350,MATCH(Gesamtpunkte[[#This Row],[Matr.-Nr.]],'3. Notenszenarien'!$A$6:$A$1048576,0)) -> #N/A | E40: =ROUNDUP(INDEX('2a.Detailpunkte'!$A$4:$A$352,MATCH('2. Punkte_Prüfung'!A40,'2a.Detailpunkte'!$D$4:$D$352,0),1)/5,1)*5 -> #N/A | F40: =Gesamtpunkte[[#This Row],[Gesamtpunkte ]]/$E$4 -> #N/A | G40: =INDEX('2a.Detailpunkte'!$B$4:$B$352,MATCH('2. Punkte_Prüfung'!A40,'2a.Detailpunkte'!$D$4:$D$352,0),1) -> #N/A | H40: =INDEX('2a.Detailpunkte'!$C$4:$C$352,MATCH('2. Punkte_Prüfung'!A40,'2a.Detailpunkte'!$D$4:$D$352,0),1) -> #N/A | I40: =Gesamtpunkte[[#This Row],[Punkte F]]/$G$4 -> #N/A | J40: =Gesamtpunkte[[#This Row],[Punkte I]]/$H$4 -> #N/A | K40: =IF(AND(ISNA(MATCH(Gesamtpunkte[[#This Row],[Matr.-Nr.]],'4. Noteneintrag'!$C$11:$C$1048576,0)),ISNUMBER(Gesamtpunkte[[#This Row],[Matr.-Nr.]])),"NEIN","JA") -> JA
...

Sheet 2a.Detailpunkte
A1: Alle mit Testversuchen | D1: Anzahl | M1: Aufgabe # | N1: =IF(ISBLANK(#REF!),"",1) -> 1 | Y1: 2 | Z1: =MID(#REF!,3,SEARCH("/",#REF!)-4) -> #REF! | AA1: =MID(#REF!,3,SEARCH("/",#REF!)-4) -> #REF! | AB1: =MID(#REF!,3,SEARCH("/",#REF!)-4) -> #REF! | AQ1: =MID(#REF!,3,SEARCH("/",#REF!)-4) -> #REF! | AR1: =MID(#REF!,3,SEARCH("/",#REF!)-4) -> #REF! | AS1: =MID(#REF!,3,SEARCH("/",#REF!)-4) -> #REF! | AT1: =MID(#REF!,3,SEARCH("/",#REF!)-4) -> #REF! | AU1: =MID(#REF!,3,SEARCH("/",#REF!)-4) -> #REF! | AV1: =MID(#REF!,3,SEARCH("/",#REF!)-4) -> #REF! | AW1: =MID(#REF!,3,SEARCH("/",#REF!)-4) -> #REF! | AX1: =MID(#REF!,3,SEARCH("/",#REF!)-4) -> #REF! | ... BG1: =MID(#REF!,3,SEARCH("/",#REF!)-4) -> #REF!
D2: =COUNT(D4:D352) -> 28 | M2: Teilgebiet | N2: FRM | O2: FRM | P2: FRM | Q2: FRM | R2: FRM | S2: FRM | T2: FRM | U2: FRM | V2: FRM | W2: FRM | X2: FRM | Y2: F | Z2: F | AA2: F | AB2: F | AC2: F | AD2: F | AE2: F | AF2: F | AG2: F | AH2: F | AI2: F | AJ2: I | AK2: I | AL2: I | AM2: I | AN2: I | AO2: I | AP2: I | AQ2: F | AR2: F | AS2: F | AT2: F | AU2: F | AV2: F | AW2: F | AX2: F | AY2: F | AZ2: I | BA2: I | BB2: I | BC2: I | BD2: I | BE2: I
A3: Gesamtpunkte | B3: ="Punkte "&'0. Definitionen'!$B$7 -> Punkte FRM | C3: ="Punkte "&'0. Definitionen'!$B$11 -> Punkte I | D3: Matr.-Nr. | E3: Nachname | F3: Vorname | G3: E-Mail-Adresse | H3: Status | I3: Begonnen am | J3: Beendet | K3: Verbrauchte Zeit | L3: Bewertung/90,00 | M3: F 1 /0,00 | N3: F 2 /5,00 | O3: F 3 /10,00 | P3: F 4 /8,00 | Q3: F 5 /10,00 | R3: F 6 /10,00 | S3: F 7 /10,00 | T3: F 8 /6,00 | U3: F 9 /3,00 | V3: F 10 /7,00 | W3: F 11 /11,00 | X3: F 12 /10,00
A4: =THE_Detailpunkte[[#This Row],[Bewertung/90,00]] -> 70.33 | B4: =SUMIFS(THE_Detailpunkte[#This Row],$E$2:$X$2,'0. Definitionen'!$B$7) -> 70.33 | C4: 0 | D4: =INDEX('1. Antritt_Prüfung'!$A$5:$H$256,MATCH(G4,'1. Antritt_Prüfung'!$C$5:$C$182,0),7) -> 3376139 | E4: Stud14 | F4: Pseudo | G4: stud14@example.local | H4: Beendet | I4: 45860.354 | J4: 45860.423 | K4: 1 Stunde 39 Minuten | L4: 70.33 | N4: 3.33 | O4: 10 | P4: 8 | Q4: 8 | R4: 8 | S4: 10 | T4: 3 | U4: 0 | V4: 7 | W4: 8 | X4: 5
A5: =THE_Detailpunkte[[#This Row],[Bewertung/90,00]] -> 68 | B5: =SUMIFS(THE_Detailpunkte[#This Row],$E$2:$X$2,'0. Definitionen'!$B$7) -> 68 | C5: 0 | D5: =INDEX('1. Antritt_Prüfung'!$A$5:$H$256,MATCH(G5,'1. Antritt_Prüfung'!$C$5:$C$182,0),7) -> 3517558 | E5: Stud29 | F5: Pseudo | G5: stud29@example.local | H5: Beendet | I5: 45860.354 | J5: 45860.423 | K5: 1 Stunde 39 Minuten | L5: 68 | N5: 5 | O5: 10 | P5: 3 | Q5: 8 | R5: 10 | S5: 10 | T5: 3 | U5: 2 | V5: 1 | W5: 9 | X5: 7
A6: =THE_Detailpunkte[[#This Row],[Bewertung/90,00]] -> 71.33 | B6: =SUMIFS(THE_Detailpunkte[#This Row],$E$2:$X$2,'0. Definitionen'!$B$7) -> 71.83 | C6: 0 | D6: =INDEX('1. Antritt_Prüfung'!$A$5:$H$256,MATCH(G6,'1. Antritt_Prüfung'!$C$5:$C$182,0),7) -> 3374601 | E6: Stud13 | F6: Pseudo | G6: stud13@example.local | H6: Beendet | I6: 45860.354 | J6: 45860.423 | K6: 1 Stunde 39 Minuten | L6: 71.33 | N6: 3.33 | O6: 10 | P6: 8 | Q6: 8 | R6: 8.5 | S6: 10 | T6: 3 | U6: 2 | V6: 7 | W6: 5 | X6: 7
A7: =THE_Detailpunkte[[#This Row],[Bewertung/90,00]] -> 78.83 | B7: =SUMIFS(THE_Detailpunkte[#This Row],$E$2:$X$2,'0. Definitionen'!$B$7) -> 78.83 | C7: 0 | D7: =INDEX('1. Antritt_Prüfung'!$A$5:$H$256,MATCH(G7,'1. Antritt_Prüfung'!$C$5:$C$182,0),7) -> 3516593 | E7: Stud28 | F7: Pseudo | G7: stud28@example.local | H7: Beendet | I7: 45860.354 | J7: 45860.424 | K7: 1 Stunde 40 Minuten | L7: 78.83 | N7: 3.33 | O7: 10 | P7: 8 | Q7: 9 | R7: 8 | S7: 8 | T7: 6 | U7: 2 | V7: 7 | W7: 11 | X7: 6.5
A8: =THE_Detailpunkte[[#This Row],[Bewertung/90,00]] -> 74.33 | B8: =SUMIFS(THE_Detailpunkte[#This Row],$E$2:$X$2,'0. Definitionen'!$B$7) -> 74.33 | C8: 0 | D8: =INDEX('1. Antritt_Prüfung'!$A$5:$H$256,MATCH(G8,'1. Antritt_Prüfung'!$C$5:$C$182,0),7) -> 3474262 | E8: Stud17 | F8: Pseudo | G8: stud17@example.local | H8: Beendet | I8: 45860.354 | J8: 45860.423 | K8: 1 Stunde 39 Minuten | L8: 74.33 | N8: 3.33 | O8: 10 | P8: 6 | Q8: 7 | R8: 8.5 | S8: 10 | T8: 3 | U8: 3 | V8: 6 | W8: 9 | X8: 8.5
A9: =THE_Detailpunkte[[#This Row],[Bewertung/90,00]] -> 66.5 | B9: =SUMIFS(THE_Detailpunkte[#This Row],$E$2:$X$2,'0. Definitionen'!$B$7) -> 66.5 | C9: 0 | D9: =INDEX('1. Antritt_Prüfung'!$A$5:$H$256,MATCH(G9,'1. Antritt_Prüfung'!$C$5:$C$182,0),7) -> 3474220 | E9: Stud16 | F9: Pseudo | G9: stud16@example.local | H9: Beendet | I9: 45860.354 | J9: 45860.423 | K9: 1 Stunde 39 Minuten | L9: 66.5 | N9: 5 | O9: 10 | P9: 8 | Q9: 8 | R9: 7 | S9: 10 | T9: 0 | U9: 2 | V9: 4 | W9: 4 | X9: 8.5
A10: =THE_Detailpunkte[[#This Row],[Bewertung/90,00]] -> 71.5 | B10: =SUMIFS(THE_Detailpunkte[#This Row],$E$2:$X$2,'0. Definitionen'!$B$7) -> 72 | C10: 0 | D10: =INDEX('1. Antritt_Prüfung'!$A$5:$H$256,MATCH(G10,'1. Antritt_Prüfung'!$C$5:$C$182,0),7) -> 3300459 | E10: Stud08 | F10: Pseudo | G10: stud08@example.local | H10: Beendet | I10: 45860.354 | J10: 45860.423 | K10: 1 Stunde 39 Minuten | L10: 71.5 | N10: 2.5 | O10: 10 | P10: 8 | Q10: 8 | R10: 8 | S10: 10 | T10: 3.5 | U10: 2 | V10: 7 | W10: 6 | X10: 7
A11: =THE_Detailpunkte[[#This Row],[Bewertung/90,00]] -> 77 | B11: =SUMIFS(THE_Detailpunkte[#This Row],$E$2:$X$2,'0. Definitionen'!$B$7) -> 77 | C11: 0 | D11: =INDEX('1. Antritt_Prüfung'!$A$5:$H$256,MATCH(G11,'1. Antritt_Prüfung'!$C$5:$C$182,0),7) -> 3513448 | E11: Stud25 | F11: Pseudo | G11: stud25@example.local | H11: Beendet | I11: 45860.354 | J11: 45860.424 | K11: 1 Stunde 39 Minuten | L11: 77 | N11: 5 | O11: 10 | P11: 8 | Q11: 8 | R11: 8 | S11: 10 | T11: 6 | U11: 2 | V11: 7 | W11: 9 | X11: 4
A12: =THE_Detailpunkte[[#This Row],[Bewertung/90,00]] -> 77 | B12: =SUMIFS(THE_Detailpunkte[#This Row],$E$2:$X$2,'0. Definitionen'!$B$7) -> 77 | C12: 0 | D12: =INDEX('1. Antritt_Prüfung'!$A$5:$H$256,MATCH(G12,'1. Antritt_Prüfung'!$C$5:$C$182,0),7) -> 3314377 | E12: Stud10 | F12: Pseudo | G12: stud10@example.local | H12: Beendet | I12: 45860.354 | J12: 45860.423 | K12: 1 Stunde 39 Minuten | L12: 77 | N12: 5 | O12: 10 | P12: 8 | Q12: 7 | R12: 10 | S12: 10 | T12: 3 | U12: 2 | V12: 7 | W12: 8 | X12: 7
A13: =THE_Detailpunkte[[#This Row],[Bewertung/90,00]] -> 82.5 | B13: =SUMIFS(THE_Detailpunkte[#This Row],$E$2:$X$2,'0. Definitionen'!$B$7) -> 85.5 | C13: 0 | D13: =INDEX('1. Antritt_Prüfung'!$A$5:$H$256,MATCH(G13,'1. Antritt_Prüfung'!$C$5:$C$182,0),7) -> 3478653 | E13: Stud21 | F13: Pseudo | G13: stud21@example.local | H13: Beendet | I13: 45860.354 | J13: 45860.423 | K13: 1 Stunde 39 Minuten | L13: 82.5 | N13: 5 | O13: 10 | P13: 8 | Q13: 8 | R13: 10 | S13: 10 | T13: 6 | U13: 3 | V13: 7 | W13: 11 | X13: 7.5
A14: =THE_Detailpunkte[[#This Row],[Bewertung/90,00]] -> 76.5 | B14: =SUMIFS(THE_Detailpunkte[#This Row],$E$2:$X$2,'0. Definitionen'!$B$7) -> 76.5 | C14: 0 | D14: =INDEX('1. Antritt_Prüfung'!$A$5:$H$256,MATCH(G14,'1. Antritt_Prüfung'!$C$5:$C$182,0),7) -> 3478426 | E14: Stud20 | F14: Pseudo | G14: stud20@example.local | H14: Beendet | I14: 45860.354 | J14: 45860.423 | K14: 1 Stunde 39 Minuten | L14: 76.5 | N14: 5 | O14: 10 | P14: 8 | Q14: 9 | R14: 6.5 | S14: 10 | T14: 3 | U14: 2 | V14: 7 | W14: 9 | X14: 7
A15: =THE_Detailpunkte[[#This Row],[Bewertung/90,00]] -> 75.5 | B15: =SUMIFS(THE_Detailpunkte[#This Row],$E$2:$X$2,'0. Definitionen'!$B$7) -> 75.5 | C15: 0 | D15: =INDEX('1. Antritt_Prüfung'!$A$5:$H$256,MATCH(G15,'1. Antritt_Prüfung'!$C$5:$C$182,0),7) -> 3202847 | E15: Stud02 | F15: Pseudo | G15: stud02@example.local | H15: Beendet | I15: 45860.354 | J15: 45860.423 | K15: 1 Stunde 38 Minuten | L15: 75.5 | N15: 5 | O15: 10 | P15: 8 | Q15: 8 | R15: 8.5 | S15: 10 | T15: 3 | U15: 2 | V15: 6 | W15: 8 | X15: 7
... A28: =THE_Detailpunkte[[#This Row],[Bewertung/90,00]] -> 70.33 | B28: =SUMIFS(THE_Detailpunkte[#This Row],$E$2:$X$2,'0. Definitionen'!$B$7) -> 70.33 | C28: 0 | D28: =INDEX('1. Antritt_Prüfung'!$A$5:$H$256,MATCH(G28,'1. Antritt_Prüfung'!$C$5:$C$182,0),7) -> 3274772 | E28: Stud06 | F28: Pseudo | G28: stud06@example.local | H28: Beendet | I28: 45860.354 | J28: 45860.417 | K28: 1 Stunde 31 Minuten | L28: 70.33 | N28: 3.33 | O28: 10 | P28: 8 | Q28: 5 | R28: 7.5 | S28: 10 | T28: 3 | U28: 3 | V28: 1 | W28: 11 | X28: 8.5
A29: =THE_Detailpunkte[[#This Row],[Bewertung/90,00]] -> 61.33 | B29: =SUMIFS(THE_Detailpunkte[#This Row],$E$2:$X$2,'0. Definitionen'!$B$7) -> 61.33 | C29: 0 | D29: =INDEX('1. Antritt_Prüfung'!$A$5:$H$256,MATCH(G29,'1. Antritt_Prüfung'!$C$5:$C$182,0),7) -> 3514106 | E29: Stud27 | F29: Pseudo | G29: stud27@example.local | H29: Beendet | I29: 45860.354 | J29: 45860.424 | K29: 1 Stunde 39 Minuten | L29: 61.33 | N29: 3.33 | O29: 10 | P29: 8 | Q29: 2 | R29: 6 | S29: 10 | T29: 6 | U29: 3 | V29: 4 | W29: 9
A30: =THE_Detailpunkte[[#This Row],[Bewertung/90,00]] -> 74.33 | B30: =SUMIFS(THE_Detailpunkte[#This Row],$E$2:$X$2,'0. Definitionen'!$B$7) -> 74.33 | C30: 0 | D30: =INDEX('1. Antritt_Prüfung'!$A$5:$H$256,MATCH(G30,'1. Antritt_Prüfung'!$C$5:$C$182,0),7) -> 3477713 | E30: Stud19 | F30: Pseudo | G30: stud19@example.local | H30: Beendet | I30: 45860.354 | J30: 45860.424 | K30: 1 Stunde 39 Minuten | L30: 74.33 | N30: 3.33 | O30: 10 | P30: 8 | Q30: 8 | R30: 7 | S30: 10 | T30: 3 | U30: 1 | V30: 7 | W30: 11 | X30: 6
A31: =THE_Detailpunkte[[#This Row],[Bewertung/90,00]] -> 78 | B31: =SUMIFS(THE_Detailpunkte[#This Row],$E$2:$X$2,'0. Definitionen'!$B$7) -> 78 | C31: 0 | D31: =INDEX('1. Antritt_Prüfung'!$A$5:$H$256,MATCH(G31,'1. Antritt_Prüfung'!$C$5:$C$182,0),7) -> 3491126 | E31: Stud24 | F31: Pseudo | G31: stud24@example.local | H31: Beendet | I31: 45860.354 | J31: 45860.424 | K31: 1 Stunde 40 Minuten | L31: 78 | N31: 5 | O31: 9 | P31: 8 | Q31: 10 | R31: 10 | S31: 10 | T31: 6 | U31: 1 | V31: 7 | W31: 5 | X31: 7
A32: =THE_Detailpunkte[[#This Row],[Bewertung/90,00]] -> #VALUE! | B32: =SUMIFS(THE_Detailpunkte[#This Row],$E$2:$X$2,'0. Definitionen'!$B$7) -> #VALUE! | C32: 0 | D32: =INDEX('1. Antritt_Prüfung'!$A$5:$H$256,MATCH(G32,'1. Antritt_Prüfung'!$C$5:$C$182,0),7) -> #N/A
A33: =THE_Detailpunkte[[#This Row],[Bewertung/90,00]] -> #VALUE! | B33: =SUMIFS(THE_Detailpunkte[#This Row],$E$2:$X$2,'0. Definitionen'!$B$7) -> #VALUE! | C33: 0 | D33: =INDEX('1. Antritt_Prüfung'!$A$5:$H$256,MATCH(G33,'1. Antritt_Prüfung'!$C$5:$C$182,0),7) -> #N/A
A34: =THE_Detailpunkte[[#This Row],[Bewertung/90,00]] -> #VALUE! | B34: =SUMIFS(THE_Detailpunkte[#This Row],$E$2:$X$2,'0. Definitionen'!$B$7) -> #VALUE! | C34: 0 | D34: =INDEX('1. Antritt_Prüfung'!$A$5:$H$256,MATCH(G34,'1. Antritt_Prüfung'!$C$5:$C$182,0),7) -> #N/A
A35: =THE_Detailpunkte[[#This Row],[Bewertung/90,00]] -> #VALUE! | B35: =SUMIFS(THE_Detailpunkte[#This Row],$E$2:$X$2,'0. Definitionen'!$B$7) -> #VALUE! | C35: 0 | D35: =INDEX('1. Antritt_Prüfung'!$A$5:$H$256,MATCH(G35,'1. Antritt_Prüfung'!$C$5:$C$182,0),7) -> #N/A
A36: =THE_Detailpunkte[[#This Row],[Bewertung/90,00]] -> #VALUE! | B36: =SUMIFS(THE_Detailpunkte[#This Row],$E$2:$X$2,'0. Definitionen'!$B$7) -> #VALUE! | C36: 0 | D36: =INDEX('1. Antritt_Prüfung'!$A$5:$H$256,MATCH(G36,'1. Antritt_Prüfung'!$C$5:$C$182,0),7) -> #N/A
A37: =THE_Detailpunkte[[#This Row],[Bewertung/90,00]] -> #VALUE! | B37: =SUMIFS(THE_Detailpunkte[#This Row],$E$2:$X$2,'0. Definitionen'!$B$7) -> #VALUE! | C37: 0 | D37: =INDEX('1. Antritt_Prüfung'!$A$5:$H$256,MATCH(G37,'1. Antritt_Prüfung'!$C$5:$C$182,0),7) -> #N/A
A38: =THE_Detailpunkte[[#This Row],[Bewertung/90,00]] -> #VALUE! | B38: =SUMIFS(THE_Detailpunkte[#This Row],$E$2:$X$2,'0. Definitionen'!$B$7) -> #VALUE! | C38: 0 | D38: =INDEX('1. Antritt_Prüfung'!$A$5:$H$256,MATCH(G38,'1. Antritt_Prüfung'!$C$5:$C$182,0),7) -> #N/A
A39: =THE_Detailpunkte[[#This Row],[Bewertung/90,00]] -> #VALUE! | B39: =SUMIFS(THE_Detailpunkte[#This Row],$E$2:$X$2,'0. Definitionen'!$B$7) -> #VALUE! | C39: 0 | D39: =INDEX('1. Antritt_Prüfung'!$A$5:$H$256,MATCH(G39,'1. Antritt_Prüfung'!$C$5:$C$182,0),7) -> #N/A
A40: =THE_Detailpunkte[[#This Row],[Bewertung/90,00]] -> #VALUE! | B40: =SUMIFS(THE_Detailpunkte[#This Row],$E$2:$X$2,'0. Definitionen'!$B$7) -> #VALUE! | C40: 0 | D40: =INDEX('1. Antritt_Prüfung'!$A$5:$H$256,MATCH(G40,'1. Antritt_Prüfung'!$C$5:$C$182,0),7) -> #N/A
A41: =THE_Detailpunkte[[#This Row],[Bewertung/90,00]] -> #VALUE! | B41: =SUMIFS(THE_Detailpunkte[#This Row],$E$2:$X$2,'0. Definitionen'!$B$7) -> #VALUE! | C41: 0 | D41: =INDEX('1. Antritt_Prüfung'!$A$5:$H$256,MATCH(G41,'1. Antritt_Prüfung'!$C$5:$C$182,0),7) -> #N/A
A42: =THE_Detailpunkte[[#This Row],[Bewertung/90,00]] -> #VALUE! | B42: =SUMIFS(THE_Detailpunkte[#This Row],$E$2:$X$2,'0. Definitionen'!$B$7) -> #VALUE! | C42: 0 | D42: =INDEX('1. Antritt_Prüfung'!$A$5:$H$256,MATCH(G42,'1. Antritt_Prüfung'!$C$5:$C$182,0),7) -> #N/A
A43: =THE_Detailpunkte[[#This Row],[Bewertung/90,00]] -> #VALUE! | B43: =SUMIFS(THE_Detailpunkte[#This Row],$E$2:$X$2,'0. Definitionen'!$B$7) -> #VALUE! | C43: 0 | D43: =INDEX('1. Antritt_Prüfung'!$A$5:$H$256,MATCH(G43,'1. Antritt_Prüfung'!$C$5:$C$182,0),7) -> #N/A
... A352: =THE_Detailpunkte[[#This Row],[Bewertung/90,00]] -> #VALUE! | B352: =SUMIFS(THE_Detailpunkte[#This Row],$E$2:$X$2,'0. Definitionen'!$B$7) -> #VALUE! | C352: 0 | D352: =INDEX('1. Antritt_Prüfung'!$A$5:$H$256,MATCH(G352,'1. Antritt_Prüfung'!$C$5:$C$182,0),7) -> #N/A

Sheet 3. Notenszenarien
A2: wird aus Notengebung automatisch eingefügt | O2: ="Szenario 1: "&P4&" Punkte - "&TEXT(Q4,"0.0%") -> Szenario 1: 45 Punkte - 50% | S2: ="Szenario 1: "&P4&" Punkte - Stand: "&TEXT(TODAY(),"JJJJ-MM-TT hh:MM")& " (Schrittweite: "&P5&" Punkte)" -> Szenario 1: 45 Punkte - Stand: 2026-07-17 00:00 (Schrittweite: 4,5 Punkte)
F3: Note | I3: Auswahl Szenario | J3: Punkte bis nächste Note | K3: Hilfsrechnung Punkte nächste Note | O3: Gesamtpunkte | P3: 90 | S3: Note | T3: Note ab | U3: Anzahl | V3: Anteil | W3: Anzahl | X3: Anteil
F4: Szenario 1 | G4: Szenario 2 | H4: Szenario 3 | K4: =F4 -> Szenario 1 | L4: =G4 -> Szenario 2 | M4: =H4 -> Szenario 3 | O4: Bestehensgrenze | P4: 45 | Q4: =P4/P3 -> 0.5 | S4: 1 | T4: =T5+P5 -> 85.5 | U4: =COUNTIF(F6:F1048576,1) -> 1 | V4: =U4/U15 -> 0.035714286 | W4: =SUM(U4:U5) -> 6 | X4: =W4/W15 -> 0.21428571 | Y4: =T4/$P$3 -> 0.95
A5: Matr.Nr. | B5: Name | C5: Vorname | D5: Versuch | E5: Punkte | F5: =P4 -> 45 | G5: =P21 -> 40 | H5: =P38 -> 35 | I5: Szenario 1 | J5: =I5 -> Szenario 1 | K5: =F5 -> 45 | L5: =G5 -> 40 | M5: =H5 -> 35 | O5: Schrittweite | P5: =ROUND((P3-P4)/COUNT(S4:S13),1) -> 4.5 | S5: 1.3 | T5: =T6+P5 -> 81 | U5: =COUNTIF(F6:F1048576,1.3) -> 5 | V5: =U5/U15 -> 0.17857143 | Y5: =T5/$P$3 -> 0.9
